Workbook

Sheet التعليمات
A1: نظام إنشاء اختبارات متعددة للطالبات
A3: يحتوي الاختبار على 50 سؤالًا: 20 صح/خطأ + 30 اختيارًا من متعدد.
A4: ورقة «الطالبات»: أدخل أسماء الطالبات وأرقام الجلوس.
A5: ورقة «بنك الأسئلة»: تحتوي معرفات الأسئلة، مع صور الأسئلة الأصلية المقتصة من الورقتين المرفوعتين.
A6: ورقة «توليد النماذج»: لكل طالبة يتم إنشاء ترتيب عشوائي لمعرفات الأسئلة. لا يتم اختراع نصوص أو إجابات غير واضحة من الصور.
A7: ورقة «الإجابات»: مكان لإدخال مفتاح الإجابة الصحيح (ص/خ أو أ/ب/ج/د)، وبعد إدخاله يمكن استخدامه للتصحيح.
A8: ملاحظة: الصور المرفوعة لا تُظهر مفتاح الإجابات بشكل موثوق؛ لذلك تركت خانة الإجابة الصحيحة فارغة بدل تخمينها.

Sheet الطالبات
A1: م | B1: اسم الطالبة | C1: رقم الجلوس | D1: الصف | E1: الشعبة
A2: 1
A3: 2
A4: 3
A5: 4
A6: 5
A7: 6
A8: 7
A9: 8
A10: 9
A11: 10
A12: 11
A13: 12
... A51: 50

Sheet بنك الأسئلة
A1: المعرف | B1: النوع | C1: رقم السؤال | D1: نص/صورة السؤال | E1: الإجابة الصحيحة | F1: ملاحظات
A2: TF01 | B2: صح/خطأ | C2: 1 | D2: الصورة الأصلية للسؤال (للحفاظ على النص كما ورد في الورقة) | F2: أدخل الإجابة الصحيحة يدويًا
A3: TF02 | B3: صح/خطأ | C3: 2 | D3: الصورة الأصلية للسؤال (للحفاظ على النص كما ورد في الورقة) | F3: أدخل الإجابة الصحيحة يدويًا
A4: TF03 | B4: صح/خطأ | C4: 3 | D4: الصورة الأصلية للسؤال (للحفاظ على النص كما ورد في الورقة) | F4: أدخل الإجابة الصحيحة يدويًا
A5: TF04 | B5: صح/خطأ | C5: 4 | D5: الصورة الأصلية للسؤال (للحفاظ على النص كما ورد في الورقة) | F5: أدخل الإجابة الصحيحة يدويًا
A6: TF05 | B6: صح/خطأ | C6: 5 | D6: الصورة الأصلية للسؤال (للحفاظ على النص كما ورد في الورقة) | F6: أدخل الإجابة الصحيحة يدويًا
A7: TF06 | B7: صح/خطأ | C7: 6 | D7: الصورة الأصلية للسؤال (للحفاظ على النص كما ورد في الورقة) | F7: أدخل الإجابة الصحيحة يدويًا
A8: TF07 | B8: صح/خطأ | C8: 7 | D8: الصورة الأصلية للسؤال (للحفاظ على النص كما ورد في الورقة) | F8: أدخل الإجابة الصحيحة يدويًا
A9: TF08 | B9: صح/خطأ | C9: 8 | D9: الصورة الأصلية للسؤال (للحفاظ على النص كما ورد في الورقة) | F9: أدخل الإجابة الصحيحة يدويًا
A10: TF09 | B10: صح/خطأ | C10: 9 | D10: الصورة الأصلية للسؤال (للحفاظ على النص كما ورد في الورقة) | F10: أدخل الإجابة الصحيحة يدويًا
A11: TF10 | B11: صح/خطأ | C11: 10 | D11: الصورة الأصلية للسؤال (للحفاظ على النص كما ورد في الورقة) | F11: أدخل الإجابة الصحيحة يدويًا
A12: TF11 | B12: صح/خطأ | C12: 11 | D12: الصورة الأصلية للسؤال (للحفاظ على النص كما ورد في الورقة) | F12: أدخل الإجابة الصحيحة يدويًا
A13: TF12 | B13: صح/خطأ | C13: 12 | D13: الصورة الأصلية للسؤال (للحفاظ على النص كما ورد في الورقة) | F13: أدخل الإجابة الصحيحة يدويًا
... A51: MC30 | B51: اختيار من متعدد | C51: 30 | D51: الصورة الأصلية للسؤال (للحفاظ على النص كما ورد في الورقة) | F51: أدخل الإجابة الصحيحة يدويًا

Sheet مفتاح الإجابة
A1: المعرف | B1: نوع السؤال | C1: الإجابة الصحيحة
A2: TF01 | B2: صح/خطأ
A3: TF02 | B3: صح/خطأ
A4: TF03 | B4: صح/خطأ
A5: TF04 | B5: صح/خطأ
A6: TF05 | B6: صح/خطأ
A7: TF06 | B7: صح/خطأ
A8: TF07 | B8: صح/خطأ
A9: TF08 | B9: صح/خطأ
A10: TF09 | B10: صح/خطأ
A11: TF10 | B11: صح/خطأ
A12: TF11 | B12: صح/خطأ
A13: TF12 | B13: صح/خطأ
... A51: MC30 | B51: اختيار من متعدد

Sheet توليد النماذج
A1: مولد الاختبارات | DA1: المعرفات
A2: ملاحظة: عند فتح الملف في Excel، اضغط F9 لإعادة توليد الترتيب العشوائي. | DA2: TF01
DA3: TF02
A4: اسم الطالبة | B4: رقم الجلوس | C4: س1 | D4: س2 | E4: س3 | F4: س4 | G4: س5 | H4: س6 | I4: س7 | J4: س8 | K4: س9 | L4: س10 | M4: س11 | N4: س12 | O4: س13 | P4: س14 | Q4: س15 | R4: س16 | S4: س17 | T4: س18 | U4: س19 | V4: س20 | W4: س21 | X4: س22 | Y4: س23 | Z4: س24 | AA4: س25 | AB4: س26 | AC4: س27 | AD4: س28 | AE4: س29 | AF4: س30 | AG4: س31 | AH4: س32 | AI4: س33 | AJ4: س34 | AK4: س35 | AL4: س36 | AM4: س37 | AN4: س38 | AO4: س39 | AP4: س40 | AQ4: س41 | AR4: س42 | AS4: س43 | AT4: س44 | AU4: س45 | AV4: س46 | AW4: س47 | AX4: س48 | AY4: س49 | AZ4: س50 | DA4: TF03
A5: =IF(الطالبات!B2="","",الطالبات!B2) | B5: =IF(الطالبات!C2="","",الطالبات!C2) | C5: =IF($A5="","",INDEX($DA$2:$DA$21,MATCH(SMALL($BB5:$BU5,1),$BB5:$BU5,0))) | D5: =IF($A5="","",INDEX($DA$2:$DA$21,MATCH(SMALL($BB5:$BU5,2),$BB5:$BU5,0))) | E5: =IF($A5="","",INDEX($DA$2:$DA$21,MATCH(SMALL($BB5:$BU5,3),$BB5:$BU5,0))) | F5: =IF($A5="","",INDEX($DA$2:$DA$21,MATCH(SMALL($BB5:$BU5,4),$BB5:$BU5,0))) | G5: =IF($A5="","",INDEX($DA$2:$DA$21,MATCH(SMALL($BB5:$BU5,5),$BB5:$BU5,0))) | H5: =IF($A5="","",INDEX($DA$2:$DA$21,MATCH(SMALL($BB5:$BU5,6),$BB5:$BU5,0))) | I5: =IF($A5="","",INDEX($DA$2:$DA$21,MATCH(SMALL($BB5:$BU5,7),$BB5:$BU5,0))) | J5: =IF($A5="","",INDEX($DA$2:$DA$21,MATCH(SMALL($BB5:$BU5,8),$BB5:$BU5,0))) | K5: =IF($A5="","",INDEX($DA$2:$DA$21,MATCH(SMALL($BB5:$BU5,9),$BB5:$BU5,0))) | L5: =IF($A5="","",INDEX($DA$2:$DA$21,MATCH(SMALL($BB5:$BU5,10),$BB5:$BU5,0))) | M5: =IF($A5="","",INDEX($DA$2:$DA$21,MATCH(SMALL($BB5:$BU5,11),$BB5:$BU5,0))) | N5: =IF($A5="","",INDEX($DA$2:$DA$21,MATCH(SMALL($BB5:$BU5,12),$BB5:$BU5,0))) | O5: =IF($A5="","",INDEX($DA$2:$DA$21,MATCH(SMALL($BB5:$BU5,13),$BB5:$BU5,0))) | P5: =IF($A5="","",INDEX($DA$2:$DA$21,MATCH(SMALL($BB5:$BU5,14),$BB5:$BU5,0))) | Q5: =IF($A5="","",INDEX($DA$2:$DA$21,MATCH(SMALL($BB5:$BU5,15),$BB5:$BU5,0))) | R5: =IF($A5="","",INDEX($DA$2:$DA$21,MATCH(SMALL($BB5:$BU5,16),$BB5:$BU5,0))) | S5: =IF($A5="","",INDEX($DA$2:$DA$21,MATCH(SMALL($BB5:$BU5,17),$BB5:$BU5,0))) | T5: =IF($A5="","",INDEX($DA$2:$DA$21,MATCH(SMALL($BB5:$BU5,18),$BB5:$BU5,0))) | U5: =IF($A5="","",INDEX($DA$2:$DA$21,MATCH(SMALL($BB5:$BU5,19),$BB5:$BU5,0))) | V5: =IF($A5="","",INDEX($DA$2:$DA$21,MATCH(SMALL($BB5:$BU5,20),$BB5:$BU5,0))) | W5: =IF($A5="","",INDEX($DA$22:$DA$51,MATCH(SMALL($BV5:$CY5,1),$BV5:$CY5,0))) | X5: =IF($A5="","",INDEX($DA$22:$DA$51,MATCH(SMALL($BV5:$CY5,2),$BV5:$CY5,0))) | Y5: =IF($A5="","",INDEX($DA$22:$DA$51,MATCH(SMALL($BV5:$CY5,3),$BV5:$CY5,0))) | Z5: =IF($A5="","",INDEX($DA$22:$DA$51,MATCH(SMALL($BV5:$CY5,4),$BV5:$CY5,0))) | AA5: =IF($A5="","",INDEX($DA$22:$DA$51,MATCH(SMALL($BV5:$CY5,5),$BV5:$CY5,0))) | AB5: =IF($A5="","",INDEX($DA$22:$DA$51,MATCH(SMALL($BV5:$CY5,6),$BV5:$CY5,0))) | AC5: =IF($A5="","",INDEX($DA$22:$DA$51,MATCH(SMALL($BV5:$CY5,7),$BV5:$CY5,0))) | AD5: =IF($A5="","",INDEX($DA$22:$DA$51,MATCH(SMALL($BV5:$CY5,8),$BV5:$CY5,0))) | AE5: =IF($A5="","",INDEX($DA$22:$DA$51,MATCH(SMALL($BV5:$CY5,9),$BV5:$CY5,0))) | AF5: =IF($A5="","",INDEX($DA$22:$DA$51,MATCH(SMALL($BV5:$CY5,10),$BV5:$CY5,0))) | AG5: =IF($A5="","",INDEX($DA$22:$DA$51,MATCH(SMALL($BV5:$CY5,11),$BV5:$CY5,0))) | AH5: =IF($A5="","",INDEX($DA$22:$DA$51,MATCH(SMALL($BV5:$CY5,12),$BV5:$CY5,0))) | AI5: =IF($A5="","",INDEX($DA$22:$DA$51,MATCH(SMALL($BV5:$CY5,13),$BV5:$CY5,0))) | AJ5: =IF($A5="","",INDEX($DA$22:$DA$51,MATCH(SMALL($BV5:$CY5,14),$BV5:$CY5,0))) | AK5: =IF($A5="","",INDEX($DA$22:$DA$51,MATCH(SMALL($BV5:$CY5,15),$BV5:$CY5,0))) | AL5: =IF($A5="","",INDEX($DA$22:$DA$51,MATCH(SMALL($BV5:$CY5,16),$BV5:$CY5,0))) | AM5: =IF($A5="","",INDEX($DA$22:$DA$51,MATCH(SMALL($BV5:$CY5,17),$BV5:$CY5,0))) | AN5: =IF($A5="","",INDEX($DA$22:$DA$51,MATCH(SMALL($BV5:$CY5,18),$BV5:$CY5,0))) | AO5: =IF($A5="","",INDEX($DA$22:$DA$51,MATCH(SMALL($BV5:$CY5,19),$BV5:$CY5,0))) | AP5: =IF($A5="","",INDEX($DA$22:$DA$51,MATCH(SMALL($BV5:$CY5,20),$BV5:$CY5,0))) | AQ5: =IF($A5="","",INDEX($DA$22:$DA$51,MATCH(SMALL($BV5:$CY5,21),$BV5:$CY5,0))) | AR5: =IF($A5="","",INDEX($DA$22:$DA$51,MATCH(SMALL($BV5:$CY5,22),$BV5:$CY5,0))) | AS5: =IF($A5="","",INDEX($DA$22:$DA$51,MATCH(SMALL($BV5:$CY5,23),$BV5:$CY5,0))) | AT5: =IF($A5="","",INDEX($DA$22:$DA$51,MATCH(SMALL($BV5:$CY5,24),$BV5:$CY5,0))) | AU5: =IF($A5="","",INDEX($DA$22:$DA$51,MATCH(SMALL($BV5:$CY5,25),$BV5:$CY5,0))) | AV5: =IF($A5="","",INDEX($DA$22:$DA$51,MATCH(SMALL($BV5:$CY5,26),$BV5:$CY5,0))) | AW5: =IF($A5="","",INDEX($DA$22:$DA$51,MATCH(SMALL($BV5:$CY5,27),$BV5:$CY5,0))) | AX5: =IF($A5="","",INDEX($DA$22:$DA$51,MATCH(SMALL($BV5:$CY5,28),$BV5:$CY5,0))) | AY5: =IF($A5="","",INDEX($DA$22:$DA$51,MATCH(SMALL($BV5:$CY5,29),$BV5:$CY5,0))) | AZ5: =IF($A5="","",INDEX($DA$22:$DA$51,MATCH(SMALL($BV5:$CY5,30),$BV5:$CY5,0))) | BB5: =RAND() | BC5: =RAND() | BD5: =RAND() | BE5: =RAND() | BF5: =RAND() | BG5: =RAND() | BH5: =RAND() | BI5: =RAND() | ... CY5: =RAND() | DA5: TF04
A6: =IF(الطالبات!B3="","",الطالبات!B3) | B6: =IF(الطالبات!C3="","",الطالبات!C3) | C6: =IF($A6="","",INDEX($DA$2:$DA$21,MATCH(SMALL($BB6:$BU6,1),$BB6:$BU6,0))) | D6: =IF($A6="","",INDEX($DA$2:$DA$21,MATCH(SMALL($BB6:$BU6,2),$BB6:$BU6,0))) | E6: =IF($A6="","",INDEX($DA$2:$DA$21,MATCH(SMALL($BB6:$BU6,3),$BB6:$BU6,0))) | F6: =IF($A6="","",INDEX($DA$2:$DA$21,MATCH(SMALL($BB6:$BU6,4),$BB6:$BU6,0))) | G6: =IF($A6="","",INDEX($DA$2:$DA$21,MATCH(SMALL($BB6:$BU6,5),$BB6:$BU6,0))) | H6: =IF($A6="","",INDEX($DA$2:$DA$21,MATCH(SMALL($BB6:$BU6,6),$BB6:$BU6,0))) | I6: =IF($A6="","",INDEX($DA$2:$DA$21,MATCH(SMALL($BB6:$BU6,7),$BB6:$BU6,0))) | J6: =IF($A6="","",INDEX($DA$2:$DA$21,MATCH(SMALL($BB6:$BU6,8),$BB6:$BU6,0))) | K6: =IF($A6="","",INDEX($DA$2:$DA$21,MATCH(SMALL($BB6:$BU6,9),$BB6:$BU6,0))) | L6: =IF($A6="","",INDEX($DA$2:$DA$21,MATCH(SMALL($BB6:$BU6,10),$BB6:$BU6,0))) | M6: =IF($A6="","",INDEX($DA$2:$DA$21,MATCH(SMALL($BB6:$BU6,11),$BB6:$BU6,0))) | N6: =IF($A6="","",INDEX($DA$2:$DA$21,MATCH(SMALL($BB6:$BU6,12),$BB6:$BU6,0))) | O6: =IF($A6="","",INDEX($DA$2:$DA$21,MATCH(SMALL($BB6:$BU6,13),$BB6:$BU6,0))) | P6: =IF($A6="","",INDEX($DA$2:$DA$21,MATCH(SMALL($BB6:$BU6,14),$BB6:$BU6,0))) | Q6: =IF($A6="","",INDEX($DA$2:$DA$21,MATCH(SMALL($BB6:$BU6,15),$BB6:$BU6,0))) | R6: =IF($A6="","",INDEX($DA$2:$DA$21,MATCH(SMALL($BB6:$BU6,16),$BB6:$BU6,0))) | S6: =IF($A6="","",INDEX($DA$2:$DA$21,MATCH(SMALL($BB6:$BU6,17),$BB6:$BU6,0))) | T6: =IF($A6="","",INDEX($DA$2:$DA$21,MATCH(SMALL($BB6:$BU6,18),$BB6:$BU6,0))) | U6: =IF($A6="","",INDEX($DA$2:$DA$21,MATCH(SMALL($BB6:$BU6,19),$BB6:$BU6,0))) | V6: =IF($A6="","",INDEX($DA$2:$DA$21,MATCH(SMALL($BB6:$BU6,20),$BB6:$BU6,0))) | W6: =IF($A6="","",INDEX($DA$22:$DA$51,MATCH(SMALL($BV6:$CY6,1),$BV6:$CY6,0))) | X6: =IF($A6="","",INDEX($DA$22:$DA$51,MATCH(SMALL($BV6:$CY6,2),$BV6:$CY6,0))) | Y6: =IF($A6="","",INDEX($DA$22:$DA$51,MATCH(SMALL($BV6:$CY6,3),$BV6:$CY6,0))) | Z6: =IF($A6="","",INDEX($DA$22:$DA$51,MATCH(SMALL($BV6:$CY6,4),$BV6:$CY6,0))) | AA6: =IF($A6="","",INDEX($DA$22:$DA$51,MATCH(SMALL($BV6:$CY6,5),$BV6:$CY6,0))) | AB6: =IF($A6="","",INDEX($DA$22:$DA$51,MATCH(SMALL($BV6:$CY6,6),$BV6:$CY6,0))) | AC6: =IF($A6="","",INDEX($DA$22:$DA$51,MATCH(SMALL($BV6:$CY6,7),$BV6:$CY6,0))) | AD6: =IF($A6="","",INDEX($DA$22:$DA$51,MATCH(SMALL($BV6:$CY6,8),$BV6:$CY6,0))) | AE6: =IF($A6="","",INDEX($DA$22:$DA$51,MATCH(SMALL($BV6:$CY6,9),$BV6:$CY6,0))) | AF6: =IF($A6="","",INDEX($DA$22:$DA$51,MATCH(SMALL($BV6:$CY6,10),$BV6:$CY6,0))) | AG6: =IF($A6="","",INDEX($DA$22:$DA$51,MATCH(SMALL($BV6:$CY6,11),$BV6:$CY6,0))) | AH6: =IF($A6="","",INDEX($DA$22:$DA$51,MATCH(SMALL($BV6:$CY6,12),$BV6:$CY6,0))) | AI6: =IF($A6="","",INDEX($DA$22:$DA$51,MATCH(SMALL($BV6:$CY6,13),$BV6:$CY6,0))) | AJ6: =IF($A6="","",INDEX($DA$22:$DA$51,MATCH(SMALL($BV6:$CY6,14),$BV6:$CY6,0))) | AK6: =IF($A6="","",INDEX($DA$22:$DA$51,MATCH(SMALL($BV6:$CY6,15),$BV6:$CY6,0))) | AL6: =IF($A6="","",INDEX($DA$22:$DA$51,MATCH(SMALL($BV6:$CY6,16),$BV6:$CY6,0))) | AM6: =IF($A6="","",INDEX($DA$22:$DA$51,MATCH(SMALL($BV6:$CY6,17),$BV6:$CY6,0))) | AN6: =IF($A6="","",INDEX($DA$22:$DA$51,MATCH(SMALL($BV6:$CY6,18),$BV6:$CY6,0))) | AO6: =IF($A6="","",INDEX($DA$22:$DA$51,MATCH(SMALL($BV6:$CY6,19),$BV6:$CY6,0))) | AP6: =IF($A6="","",INDEX($DA$22:$DA$51,MATCH(SMALL($BV6:$CY6,20),$BV6:$CY6,0))) | AQ6: =IF($A6="","",INDEX($DA$22:$DA$51,MATCH(SMALL($BV6:$CY6,21),$BV6:$CY6,0))) | AR6: =IF($A6="","",INDEX($DA$22:$DA$51,MATCH(SMALL($BV6:$CY6,22),$BV6:$CY6,0))) | AS6: =IF($A6="","",INDEX($DA$22:$DA$51,MATCH(SMALL($BV6:$CY6,23),$BV6:$CY6,0))) | AT6: =IF($A6="","",INDEX($DA$22:$DA$51,MATCH(SMALL($BV6:$CY6,24),$BV6:$CY6,0))) | AU6: =IF($A6="","",INDEX($DA$22:$DA$51,MATCH(SMALL($BV6:$CY6,25),$BV6:$CY6,0))) | AV6: =IF($A6="","",INDEX($DA$22:$DA$51,MATCH(SMALL($BV6:$CY6,26),$BV6:$CY6,0))) | AW6: =IF($A6="","",INDEX($DA$22:$DA$51,MATCH(SMALL($BV6:$CY6,27),$BV6:$CY6,0))) | AX6: =IF($A6="","",INDEX($DA$22:$DA$51,MATCH(SMALL($BV6:$CY6,28),$BV6:$CY6,0))) | AY6: =IF($A6="","",INDEX($DA$22:$DA$51,MATCH(SMALL($BV6:$CY6,29),$BV6:$CY6,0))) | AZ6: =IF($A6="","",INDEX($DA$22:$DA$51,MATCH(SMALL($BV6:$CY6,30),$BV6:$CY6,0))) | BB6: =RAND() | BC6: =RAND() | BD6: =RAND() | BE6: =RAND() | BF6: =RAND() | BG6: =RAND() | BH6: =RAND() | BI6: =RAND() | ... CY6: =RAND() | DA6: TF05
A7: =IF(الطالبات!B4="","",الطالبات!B4) | B7: =IF(الطالبات!C4="","",الطالبات!C4) | C7: =IF($A7="","",INDEX($DA$2:$DA$21,MATCH(SMALL($BB7:$BU7,1),$BB7:$BU7,0))) | D7: =IF($A7="","",INDEX($DA$2:$DA$21,MATCH(SMALL($BB7:$BU7,2),$BB7:$BU7,0))) | E7: =IF($A7="","",INDEX($DA$2:$DA$21,MATCH(SMALL($BB7:$BU7,3),$BB7:$BU7,0))) | F7: =IF($A7="","",INDEX($DA$2:$DA$21,MATCH(SMALL($BB7:$BU7,4),$BB7:$BU7,0))) | G7: =IF($A7="","",INDEX($DA$2:$DA$21,MATCH(SMALL($BB7:$BU7,5),$BB7:$BU7,0))) | H7: =IF($A7="","",INDEX($DA$2:$DA$21,MATCH(SMALL($BB7:$BU7,6),$BB7:$BU7,0))) | I7: =IF($A7="","",INDEX($DA$2:$DA$21,MATCH(SMALL($BB7:$BU7,7),$BB7:$BU7,0))) | J7: =IF($A7="","",INDEX($DA$2:$DA$21,MATCH(SMALL($BB7:$BU7,8),$BB7:$BU7,0))) | K7: =IF($A7="","",INDEX($DA$2:$DA$21,MATCH(SMALL($BB7:$BU7,9),$BB7:$BU7,0))) | L7: =IF($A7="","",INDEX($DA$2:$DA$21,MATCH(SMALL($BB7:$BU7,10),$BB7:$BU7,0))) | M7: =IF($A7="","",INDEX($DA$2:$DA$21,MATCH(SMALL($BB7:$BU7,11),$BB7:$BU7,0))) | N7: =IF($A7="","",INDEX($DA$2:$DA$21,MATCH(SMALL($BB7:$BU7,12),$BB7:$BU7,0))) | O7: =IF($A7="","",INDEX($DA$2:$DA$21,MATCH(SMALL($BB7:$BU7,13),$BB7:$BU7,0))) | P7: =IF($A7="","",INDEX($DA$2:$DA$21,MATCH(SMALL($BB7:$BU7,14),$BB7:$BU7,0))) | Q7: =IF($A7="","",INDEX($DA$2:$DA$21,MATCH(SMALL($BB7:$BU7,15),$BB7:$BU7,0))) | R7: =IF($A7="","",INDEX($DA$2:$DA$21,MATCH(SMALL($BB7:$BU7,16),$BB7:$BU7,0))) | S7: =IF($A7="","",INDEX($DA$2:$DA$21,MATCH(SMALL($BB7:$BU7,17),$BB7:$BU7,0))) | T7: =IF($A7="","",INDEX($DA$2:$DA$21,MATCH(SMALL($BB7:$BU7,18),$BB7:$BU7,0))) | U7: =IF($A7="","",INDEX($DA$2:$DA$21,MATCH(SMALL($BB7:$BU7,19),$BB7:$BU7,0))) | V7: =IF($A7="","",INDEX($DA$2:$DA$21,MATCH(SMALL($BB7:$BU7,20),$BB7:$BU7,0))) | W7: =IF($A7="","",INDEX($DA$22:$DA$51,MATCH(SMALL($BV7:$CY7,1),$BV7:$CY7,0))) | X7: =IF($A7="","",INDEX($DA$22:$DA$51,MATCH(SMALL($BV7:$CY7,2),$BV7:$CY7,0))) | Y7: =IF($A7="","",INDEX($DA$22:$DA$51,MATCH(SMALL($BV7:$CY7,3),$BV7:$CY7,0))) | Z7: =IF($A7="","",INDEX($DA$22:$DA$51,MATCH(SMALL($BV7:$CY7,4),$BV7:$CY7,0))) | AA7: =IF($A7="","",INDEX($DA$22:$DA$51,MATCH(SMALL($BV7:$CY7,5),$BV7:$CY7,0))) | AB7: =IF($A7="","",INDEX($DA$22:$DA$51,MATCH(SMALL($BV7:$CY7,6),$BV7:$CY7,0))) | AC7: =IF($A7="","",INDEX($DA$22:$DA$51,MATCH(SMALL($BV7:$CY7,7),$BV7:$CY7,0))) | AD7: =IF($A7="","",INDEX($DA$22:$DA$51,MATCH(SMALL($BV7:$CY7,8),$BV7:$CY7,0))) | AE7: =IF($A7="","",INDEX($DA$22:$DA$51,MATCH(SMALL($BV7:$CY7,9),$BV7:$CY7,0))) | AF7: =IF($A7="","",INDEX($DA$22:$DA$51,MATCH(SMALL($BV7:$CY7,10),$BV7:$CY7,0))) | AG7: =IF($A7="","",INDEX($DA$22:$DA$51,MATCH(SMALL($BV7:$CY7,11),$BV7:$CY7,0))) | AH7: =IF($A7="","",INDEX($DA$22:$DA$51,MATCH(SMALL($BV7:$CY7,12),$BV7:$CY7,0))) | AI7: =IF($A7="","",INDEX($DA$22:$DA$51,MATCH(SMALL($BV7:$CY7,13),$BV7:$CY7,0))) | AJ7: =IF($A7="","",INDEX($DA$22:$DA$51,MATCH(SMALL($BV7:$CY7,14),$BV7:$CY7,0))) | AK7: =IF($A7="","",INDEX($DA$22:$DA$51,MATCH(SMALL($BV7:$CY7,15),$BV7:$CY7,0))) | AL7: =IF($A7="","",INDEX($DA$22:$DA$51,MATCH(SMALL($BV7:$CY7,16),$BV7:$CY7,0))) | AM7: =IF($A7="","",INDEX($DA$22:$DA$51,MATCH(SMALL($BV7:$CY7,17),$BV7:$CY7,0))) | AN7: =IF($A7="","",INDEX($DA$22:$DA$51,MATCH(SMALL($BV7:$CY7,18),$BV7:$CY7,0))) | AO7: =IF($A7="","",INDEX($DA$22:$DA$51,MATCH(SMALL($BV7:$CY7,19),$BV7:$CY7,0))) | AP7: =IF($A7="","",INDEX($DA$22:$DA$51,MATCH(SMALL($BV7:$CY7,20),$BV7:$CY7,0))) | AQ7: =IF($A7="","",INDEX($DA$22:$DA$51,MATCH(SMALL($BV7:$CY7,21),$BV7:$CY7,0))) | AR7: =IF($A7="","",INDEX($DA$22:$DA$51,MATCH(SMALL($BV7:$CY7,22),$BV7:$CY7,0))) | AS7: =IF($A7="","",INDEX($DA$22:$DA$51,MATCH(SMALL($BV7:$CY7,23),$BV7:$CY7,0))) | AT7: =IF($A7="","",INDEX($DA$22:$DA$51,MATCH(SMALL($BV7:$CY7,24),$BV7:$CY7,0))) | AU7: =IF($A7="","",INDEX($DA$22:$DA$51,MATCH(SMALL($BV7:$CY7,25),$BV7:$CY7,0))) | AV7: =IF($A7="","",INDEX($DA$22:$DA$51,MATCH(SMALL($BV7:$CY7,26),$BV7:$CY7,0))) | AW7: =IF($A7="","",INDEX($DA$22:$DA$51,MATCH(SMALL($BV7:$CY7,27),$BV7:$CY7,0))) | AX7: =IF($A7="","",INDEX($DA$22:$DA$51,MATCH(SMALL($BV7:$CY7,28),$BV7:$CY7,0))) | AY7: =IF($A7="","",INDEX($DA$22:$DA$51,MATCH(SMALL($BV7:$CY7,29),$BV7:$CY7,0))) | AZ7: =IF($A7="","",INDEX($DA$22:$DA$51,MATCH(SMALL($BV7:$CY7,30),$BV7:$CY7,0))) | BB7: =RAND() | BC7: =RAND() | BD7: =RAND() | BE7: =RAND() | BF7: =RAND() | BG7: =RAND() | BH7: =RAND() | BI7: =RAND() | ... CY7: =RAND() | DA7: TF06
A8: =IF(الطالبات!B5="","",الطالبات!B5) | B8: =IF(الطالبات!C5="","",الطالبات!C5) | C8: =IF($A8="","",INDEX($DA$2:$DA$21,MATCH(SMALL($BB8:$BU8,1),$BB8:$BU8,0))) | D8: =IF($A8="","",INDEX($DA$2:$DA$21,MATCH(SMALL($BB8:$BU8,2),$BB8:$BU8,0))) | E8: =IF($A8="","",INDEX($DA$2:$DA$21,MATCH(SMALL($BB8:$BU8,3),$BB8:$BU8,0))) | F8: =IF($A8="","",INDEX($DA$2:$DA$21,MATCH(SMALL($BB8:$BU8,4),$BB8:$BU8,0))) | G8: =IF($A8="","",INDEX($DA$2:$DA$21,MATCH(SMALL($BB8:$BU8,5),$BB8:$BU8,0))) | H8: =IF($A8="","",INDEX($DA$2:$DA$21,MATCH(SMALL($BB8:$BU8,6),$BB8:$BU8,0))) | I8: =IF($A8="","",INDEX($DA$2:$DA$21,MATCH(SMALL($BB8:$BU8,7),$BB8:$BU8,0))) | J8: =IF($A8="","",INDEX($DA$2:$DA$21,MATCH(SMALL($BB8:$BU8,8),$BB8:$BU8,0))) | K8: =IF($A8="","",INDEX($DA$2:$DA$21,MATCH(SMALL($BB8:$BU8,9),$BB8:$BU8,0))) | L8: =IF($A8="","",INDEX($DA$2:$DA$21,MATCH(SMALL($BB8:$BU8,10),$BB8:$BU8,0))) | M8: =IF($A8="","",INDEX($DA$2:$DA$21,MATCH(SMALL($BB8:$BU8,11),$BB8:$BU8,0))) | N8: =IF($A8="","",INDEX($DA$2:$DA$21,MATCH(SMALL($BB8:$BU8,12),$BB8:$BU8,0))) | O8: =IF($A8="","",INDEX($DA$2:$DA$21,MATCH(SMALL($BB8:$BU8,13),$BB8:$BU8,0))) | P8: =IF($A8="","",INDEX($DA$2:$DA$21,MATCH(SMALL($BB8:$BU8,14),$BB8:$BU8,0))) | Q8: =IF($A8="","",INDEX($DA$2:$DA$21,MATCH(SMALL($BB8:$BU8,15),$BB8:$BU8,0))) | R8: =IF($A8="","",INDEX($DA$2:$DA$21,MATCH(SMALL($BB8:$BU8,16),$BB8:$BU8,0))) | S8: =IF($A8="","",INDEX($DA$2:$DA$21,MATCH(SMALL($BB8:$BU8,17),$BB8:$BU8,0))) | T8: =IF($A8="","",INDEX($DA$2:$DA$21,MATCH(SMALL($BB8:$BU8,18),$BB8:$BU8,0))) | U8: =IF($A8="","",INDEX($DA$2:$DA$21,MATCH(SMALL($BB8:$BU8,19),$BB8:$BU8,0))) | V8: =IF($A8="","",INDEX($DA$2:$DA$21,MATCH(SMALL($BB8:$BU8,20),$BB8:$BU8,0))) | W8: =IF($A8="","",INDEX($DA$22:$DA$51,MATCH(SMALL($BV8:$CY8,1),$BV8:$CY8,0))) | X8: =IF($A8="","",INDEX($DA$22:$DA$51,MATCH(SMALL($BV8:$CY8,2),$BV8:$CY8,0))) | Y8: =IF($A8="","",INDEX($DA$22:$DA$51,MATCH(SMALL($BV8:$CY8,3),$BV8:$CY8,0))) | Z8: =IF($A8="","",INDEX($DA$22:$DA$51,MATCH(SMALL($BV8:$CY8,4),$BV8:$CY8,0))) | AA8: =IF($A8="","",INDEX($DA$22:$DA$51,MATCH(SMALL($BV8:$CY8,5),$BV8:$CY8,0))) | AB8: =IF($A8="","",INDEX($DA$22:$DA$51,MATCH(SMALL($BV8:$CY8,6),$BV8:$CY8,0))) | AC8: =IF($A8="","",INDEX($DA$22:$DA$51,MATCH(SMALL($BV8:$CY8,7),$BV8:$CY8,0))) | AD8: =IF($A8="","",INDEX($DA$22:$DA$51,MATCH(SMALL($BV8:$CY8,8),$BV8:$CY8,0))) | AE8: =IF($A8="","",INDEX($DA$22:$DA$51,MATCH(SMALL($BV8:$CY8,9),$BV8:$CY8,0))) | AF8: =IF($A8="","",INDEX($DA$22:$DA$51,MATCH(SMALL($BV8:$CY8,10),$BV8:$CY8,0))) | AG8: =IF($A8="","",INDEX($DA$22:$DA$51,MATCH(SMALL($BV8:$CY8,11),$BV8:$CY8,0))) | AH8: =IF($A8="","",INDEX($DA$22:$DA$51,MATCH(SMALL($BV8:$CY8,12),$BV8:$CY8,0))) | AI8: =IF($A8="","",INDEX($DA$22:$DA$51,MATCH(SMALL($BV8:$CY8,13),$BV8:$CY8,0))) | AJ8: =IF($A8="","",INDEX($DA$22:$DA$51,MATCH(SMALL($BV8:$CY8,14),$BV8:$CY8,0))) | AK8: =IF($A8="","",INDEX($DA$22:$DA$51,MATCH(SMALL($BV8:$CY8,15),$BV8:$CY8,0))) | AL8: =IF($A8="","",INDEX($DA$22:$DA$51,MATCH(SMALL($BV8:$CY8,16),$BV8:$CY8,0))) | AM8: =IF($A8="","",INDEX($DA$22:$DA$51,MATCH(SMALL($BV8:$CY8,17),$BV8:$CY8,0))) | AN8: =IF($A8="","",INDEX($DA$22:$DA$51,MATCH(SMALL($BV8:$CY8,18),$BV8:$CY8,0))) | AO8: =IF($A8="","",INDEX($DA$22:$DA$51,MATCH(SMALL($BV8:$CY8,19),$BV8:$CY8,0))) | AP8: =IF($A8="","",INDEX($DA$22:$DA$51,MATCH(SMALL($BV8:$CY8,20),$BV8:$CY8,0))) | AQ8: =IF($A8="","",INDEX($DA$22:$DA$51,MATCH(SMALL($BV8:$CY8,21),$BV8:$CY8,0))) | AR8: =IF($A8="","",INDEX($DA$22:$DA$51,MATCH(SMALL($BV8:$CY8,22),$BV8:$CY8,0))) | AS8: =IF($A8="","",INDEX($DA$22:$DA$51,MATCH(SMALL($BV8:$CY8,23),$BV8:$CY8,0))) | AT8: =IF($A8="","",INDEX($DA$22:$DA$51,MATCH(SMALL($BV8:$CY8,24),$BV8:$CY8,0))) | AU8: =IF($A8="","",INDEX($DA$22:$DA$51,MATCH(SMALL($BV8:$CY8,25),$BV8:$CY8,0))) | AV8: =IF($A8="","",INDEX($DA$22:$DA$51,MATCH(SMALL($BV8:$CY8,26),$BV8:$CY8,0))) | AW8: =IF($A8="","",INDEX($DA$22:$DA$51,MATCH(SMALL($BV8:$CY8,27),$BV8:$CY8,0))) | AX8: =IF($A8="","",INDEX($DA$22:$DA$51,MATCH(SMALL($BV8:$CY8,28),$BV8:$CY8,0))) | AY8: =IF($A8="","",INDEX($DA$22:$DA$51,MATCH(SMALL($BV8:$CY8,29),$BV8:$CY8,0))) | AZ8: =IF($A8="","",INDEX($DA$22:$DA$51,MATCH(SMALL($BV8:$CY8,30),$BV8:$CY8,0))) | BB8: =RAND() | BC8: =RAND() | BD8: =RAND() | BE8: =RAND() | BF8: =RAND() | BG8: =RAND() | BH8: =RAND() | BI8: =RAND() | ... CY8: =RAND() | DA8: TF07
A9: =IF(الطالبات!B6="","",الطالبات!B6) | B9: =IF(الطالبات!C6="","",الطالبات!C6) | C9: =IF($A9="","",INDEX($DA$2:$DA$21,MATCH(SMALL($BB9:$BU9,1),$BB9:$BU9,0))) | D9: =IF($A9="","",INDEX($DA$2:$DA$21,MATCH(SMALL($BB9:$BU9,2),$BB9:$BU9,0))) | E9: =IF($A9="","",INDEX($DA$2:$DA$21,MATCH(SMALL($BB9:$BU9,3),$BB9:$BU9,0))) | F9: =IF($A9="","",INDEX($DA$2:$DA$21,MATCH(SMALL($BB9:$BU9,4),$BB9:$BU9,0))) | G9: =IF($A9="","",INDEX($DA$2:$DA$21,MATCH(SMALL($BB9:$BU9,5),$BB9:$BU9,0))) | H9: =IF($A9="","",INDEX($DA$2:$DA$21,MATCH(SMALL($BB9:$BU9,6),$BB9:$BU9,0))) | I9: =IF($A9="","",INDEX($DA$2:$DA$21,MATCH(SMALL($BB9:$BU9,7),$BB9:$BU9,0))) | J9: =IF($A9="","",INDEX($DA$2:$DA$21,MATCH(SMALL($BB9:$BU9,8),$BB9:$BU9,0))) | K9: =IF($A9="","",INDEX($DA$2:$DA$21,MATCH(SMALL($BB9:$BU9,9),$BB9:$BU9,0))) | L9: =IF($A9="","",INDEX($DA$2:$DA$21,MATCH(SMALL($BB9:$BU9,10),$BB9:$BU9,0))) | M9: =IF($A9="","",INDEX($DA$2:$DA$21,MATCH(SMALL($BB9:$BU9,11),$BB9:$BU9,0))) | N9: =IF($A9="","",INDEX($DA$2:$DA$21,MATCH(SMALL($BB9:$BU9,12),$BB9:$BU9,0))) | O9: =IF($A9="","",INDEX($DA$2:$DA$21,MATCH(SMALL($BB9:$BU9,13),$BB9:$BU9,0))) | P9: =IF($A9="","",INDEX($DA$2:$DA$21,MATCH(SMALL($BB9:$BU9,14),$BB9:$BU9,0))) | Q9: =IF($A9="","",INDEX($DA$2:$DA$21,MATCH(SMALL($BB9:$BU9,15),$BB9:$BU9,0))) | R9: =IF($A9="","",INDEX($DA$2:$DA$21,MATCH(SMALL($BB9:$BU9,16),$BB9:$BU9,0))) | S9: =IF($A9="","",INDEX($DA$2:$DA$21,MATCH(SMALL($BB9:$BU9,17),$BB9:$BU9,0))) | T9: =IF($A9="","",INDEX($DA$2:$DA$21,MATCH(SMALL($BB9:$BU9,18),$BB9:$BU9,0))) | U9: =IF($A9="","",INDEX($DA$2:$DA$21,MATCH(SMALL($BB9:$BU9,19),$BB9:$BU9,0))) | V9: =IF($A9="","",INDEX($DA$2:$DA$21,MATCH(SMALL($BB9:$BU9,20),$BB9:$BU9,0))) | W9: =IF($A9="","",INDEX($DA$22:$DA$51,MATCH(SMALL($BV9:$CY9,1),$BV9:$CY9,0))) | X9: =IF($A9="","",INDEX($DA$22:$DA$51,MATCH(SMALL($BV9:$CY9,2),$BV9:$CY9,0))) | Y9: =IF($A9="","",INDEX($DA$22:$DA$51,MATCH(SMALL($BV9:$CY9,3),$BV9:$CY9,0))) | Z9: =IF($A9="","",INDEX($DA$22:$DA$51,MATCH(SMALL($BV9:$CY9,4),$BV9:$CY9,0))) | AA9: =IF($A9="","",INDEX($DA$22:$DA$51,MATCH(SMALL($BV9:$CY9,5),$BV9:$CY9,0))) | AB9: =IF($A9="","",INDEX($DA$22:$DA$51,MATCH(SMALL($BV9:$CY9,6),$BV9:$CY9,0))) | AC9: =IF($A9="","",INDEX($DA$22:$DA$51,MATCH(SMALL($BV9:$CY9,7),$BV9:$CY9,0))) | AD9: =IF($A9="","",INDEX($DA$22:$DA$51,MATCH(SMALL($BV9:$CY9,8),$BV9:$CY9,0))) | AE9: =IF($A9="","",INDEX($DA$22:$DA$51,MATCH(SMALL($BV9:$CY9,9),$BV9:$CY9,0))) | AF9: =IF($A9="","",INDEX($DA$22:$DA$51,MATCH(SMALL($BV9:$CY9,10),$BV9:$CY9,0))) | AG9: =IF($A9="","",INDEX($DA$22:$DA$51,MATCH(SMALL($BV9:$CY9,11),$BV9:$CY9,0))) | AH9: =IF($A9="","",INDEX($DA$22:$DA$51,MATCH(SMALL($BV9:$CY9,12),$BV9:$CY9,0))) | AI9: =IF($A9="","",INDEX($DA$22:$DA$51,MATCH(SMALL($BV9:$CY9,13),$BV9:$CY9,0))) | AJ9: =IF($A9="","",INDEX($DA$22:$DA$51,MATCH(SMALL($BV9:$CY9,14),$BV9:$CY9,0))) | AK9: =IF($A9="","",INDEX($DA$22:$DA$51,MATCH(SMALL($BV9:$CY9,15),$BV9:$CY9,0))) | AL9: =IF($A9="","",INDEX($DA$22:$DA$51,MATCH(SMALL($BV9:$CY9,16),$BV9:$CY9,0))) | AM9: =IF($A9="","",INDEX($DA$22:$DA$51,MATCH(SMALL($BV9:$CY9,17),$BV9:$CY9,0))) | AN9: =IF($A9="","",INDEX($DA$22:$DA$51,MATCH(SMALL($BV9:$CY9,18),$BV9:$CY9,0))) | AO9: =IF($A9="","",INDEX($DA$22:$DA$51,MATCH(SMALL($BV9:$CY9,19),$BV9:$CY9,0))) | AP9: =IF($A9="","",INDEX($DA$22:$DA$51,MATCH(SMALL($BV9:$CY9,20),$BV9:$CY9,0))) | AQ9: =IF($A9="","",INDEX($DA$22:$DA$51,MATCH(SMALL($BV9:$CY9,21),$BV9:$CY9,0))) | AR9: =IF($A9="","",INDEX($DA$22:$DA$51,MATCH(SMALL($BV9:$CY9,22),$BV9:$CY9,0))) | AS9: =IF($A9="","",INDEX($DA$22:$DA$51,MATCH(SMALL($BV9:$CY9,23),$BV9:$CY9,0))) | AT9: =IF($A9="","",INDEX($DA$22:$DA$51,MATCH(SMALL($BV9:$CY9,24),$BV9:$CY9,0))) | AU9: =IF($A9="","",INDEX($DA$22:$DA$51,MATCH(SMALL($BV9:$CY9,25),$BV9:$CY9,0))) | AV9: =IF($A9="","",INDEX($DA$22:$DA$51,MATCH(SMALL($BV9:$CY9,26),$BV9:$CY9,0))) | AW9: =IF($A9="","",INDEX($DA$22:$DA$51,MATCH(SMALL($BV9:$CY9,27),$BV9:$CY9,0))) | AX9: =IF($A9="","",INDEX($DA$22:$DA$51,MATCH(SMALL($BV9:$CY9,28),$BV9:$CY9,0))) | AY9: =IF($A9="","",INDEX($DA$22:$DA$51,MATCH(SMALL($BV9:$CY9,29),$BV9:$CY9,0))) | AZ9: =IF($A9="","",INDEX($DA$22:$DA$51,MATCH(SMALL($BV9:$CY9,30),$BV9:$CY9,0))) | BB9: =RAND() | BC9: =RAND() | BD9: =RAND() | BE9: =RAND() | BF9: =RAND() | BG9: =RAND() | BH9: =RAND() | BI9: =RAND() | ... CY9: =RAND() | DA9: TF08
A10: =IF(الطالبات!B7="","",الطالبات!B7) | B10: =IF(الطالبات!C7="","",الطالبات!C7) | C10: =IF($A10="","",INDEX($DA$2:$DA$21,MATCH(SMALL($BB10:$BU10,1),$BB10:$BU10,0))) | D10: =IF($A10="","",INDEX($DA$2:$DA$21,MATCH(SMALL($BB10:$BU10,2),$BB10:$BU10,0))) | E10: =IF($A10="","",INDEX($DA$2:$DA$21,MATCH(SMALL($BB10:$BU10,3),$BB10:$BU10,0))) | F10: =IF($A10="","",INDEX($DA$2:$DA$21,MATCH(SMALL($BB10:$BU10,4),$BB10:$BU10,0))) | G10: =IF($A10="","",INDEX($DA$2:$DA$21,MATCH(SMALL($BB10:$BU10,5),$BB10:$BU10,0))) | H10: =IF($A10="","",INDEX($DA$2:$DA$21,MATCH(SMALL($BB10:$BU10,6),$BB10:$BU10,0))) | I10: =IF($A10="","",INDEX($DA$2:$DA$21,MATCH(SMALL($BB10:$BU10,7),$BB10:$BU10,0))) | J10: =IF($A10="","",INDEX($DA$2:$DA$21,MATCH(SMALL($BB10:$BU10,8),$BB10:$BU10,0))) | K10: =IF($A10="","",INDEX($DA$2:$DA$21,MATCH(SMALL($BB10:$BU10,9),$BB10:$BU10,0))) | L10: =IF($A10="","",INDEX($DA$2:$DA$21,MATCH(SMALL($BB10:$BU10,10),$BB10:$BU10,0))) | M10: =IF($A10="","",INDEX($DA$2:$DA$21,MATCH(SMALL($BB10:$BU10,11),$BB10:$BU10,0))) | N10: =IF($A10="","",INDEX($DA$2:$DA$21,MATCH(SMALL($BB10:$BU10,12),$BB10:$BU10,0))) | O10: =IF($A10="","",INDEX($DA$2:$DA$21,MATCH(SMALL($BB10:$BU10,13),$BB10:$BU10,0))) | P10: =IF($A10="","",INDEX($DA$2:$DA$21,MATCH(SMALL($BB10:$BU10,14),$BB10:$BU10,0))) | Q10: =IF($A10="","",INDEX($DA$2:$DA$21,MATCH(SMALL($BB10:$BU10,15),$BB10:$BU10,0))) | R10: =IF($A10="","",INDEX($DA$2:$DA$21,MATCH(SMALL($BB10:$BU10,16),$BB10:$BU10,0))) | S10: =IF($A10="","",INDEX($DA$2:$DA$21,MATCH(SMALL($BB10:$BU10,17),$BB10:$BU10,0))) | T10: =IF($A10="","",INDEX($DA$2:$DA$21,MATCH(SMALL($BB10:$BU10,18),$BB10:$BU10,0))) | U10: =IF($A10="","",INDEX($DA$2:$DA$21,MATCH(SMALL($BB10:$BU10,19),$BB10:$BU10,0))) | V10: =IF($A10="","",INDEX($DA$2:$DA$21,MATCH(SMALL($BB10:$BU10,20),$BB10:$BU10,0))) | W10: =IF($A10="","",INDEX($DA$22:$DA$51,MATCH(SMALL($BV10:$CY10,1),$BV10:$CY10,0))) | X10: =IF($A10="","",INDEX($DA$22:$DA$51,MATCH(SMALL($BV10:$CY10,2),$BV10:$CY10,0))) | Y10: =IF($A10="","",INDEX($DA$22:$DA$51,MATCH(SMALL($BV10:$CY10,3),$BV10:$CY10,0))) | Z10: =IF($A10="","",INDEX($DA$22:$DA$51,MATCH(SMALL($BV10:$CY10,4),$BV10:$CY10,0))) | AA10: =IF($A10="","",INDEX($DA$22:$DA$51,MATCH(SMALL($BV10:$CY10,5),$BV10:$CY10,0))) | AB10: =IF($A10="","",INDEX($DA$22:$DA$51,MATCH(SMALL($BV10:$CY10,6),$BV10:$CY10,0))) | AC10: =IF($A10="","",INDEX($DA$22:$DA$51,MATCH(SMALL($BV10:$CY10,7),$BV10:$CY10,0))) | AD10: =IF($A10="","",INDEX($DA$22:$DA$51,MATCH(SMALL($BV10:$CY10,8),$BV10:$CY10,0))) | AE10: =IF($A10="","",INDEX($DA$22:$DA$51,MATCH(SMALL($BV10:$CY10,9),$BV10:$CY10,0))) | AF10: =IF($A10="","",INDEX($DA$22:$DA$51,MATCH(SMALL($BV10:$CY10,10),$BV10:$CY10,0))) | AG10: =IF($A10="","",INDEX($DA$22:$DA$51,MATCH(SMALL($BV10:$CY10,11),$BV10:$CY10,0))) | AH10: =IF($A10="","",INDEX($DA$22:$DA$51,MATCH(SMALL($BV10:$CY10,12),$BV10:$CY10,0))) | AI10: =IF($A10="","",INDEX($DA$22:$DA$51,MATCH(SMALL($BV10:$CY10,13),$BV10:$CY10,0))) | AJ10: =IF($A10="","",INDEX($DA$22:$DA$51,MATCH(SMALL($BV10:$CY10,14),$BV10:$CY10,0))) | AK10: =IF($A10="","",INDEX($DA$22:$DA$51,MATCH(SMALL($BV10:$CY10,15),$BV10:$CY10,0))) | AL10: =IF($A10="","",INDEX($DA$22:$DA$51,MATCH(SMALL($BV10:$CY10,16),$BV10:$CY10,0))) | AM10: =IF($A10="","",INDEX($DA$22:$DA$51,MATCH(SMALL($BV10:$CY10,17),$BV10:$CY10,0))) | AN10: =IF($A10="","",INDEX($DA$22:$DA$51,MATCH(SMALL($BV10:$CY10,18),$BV10:$CY10,0))) | AO10: =IF($A10="","",INDEX($DA$22:$DA$51,MATCH(SMALL($BV10:$CY10,19),$BV10:$CY10,0))) | AP10: =IF($A10="","",INDEX($DA$22:$DA$51,MATCH(SMALL($BV10:$CY10,20),$BV10:$CY10,0))) | AQ10: =IF($A10="","",INDEX($DA$22:$DA$51,MATCH(SMALL($BV10:$CY10,21),$BV10:$CY10,0))) | AR10: =IF($A10="","",INDEX($DA$22:$DA$51,MATCH(SMALL($BV10:$CY10,22),$BV10:$CY10,0))) | AS10: =IF($A10="","",INDEX($DA$22:$DA$51,MATCH(SMALL($BV10:$CY10,23),$BV10:$CY10,0))) | AT10: =IF($A10="","",INDEX($DA$22:$DA$51,MATCH(SMALL($BV10:$CY10,24),$BV10:$CY10,0))) | AU10: =IF($A10="","",INDEX($DA$22:$DA$51,MATCH(SMALL($BV10:$CY10,25),$BV10:$CY10,0))) | AV10: =IF($A10="","",INDEX($DA$22:$DA$51,MATCH(SMALL($BV10:$CY10,26),$BV10:$CY10,0))) | AW10: =IF($A10="","",INDEX($DA$22:$DA$51,MATCH(SMALL($BV10:$CY10,27),$BV10:$CY10,0))) | AX10: =IF($A10="","",INDEX($DA$22:$DA$51,MATCH(SMALL($BV10:$CY10,28),$BV10:$CY10,0))) | AY10: =IF($A10="","",INDEX($DA$22:$DA$51,MATCH(SMALL($BV10:$CY10,29),$BV10:$CY10,0))) | AZ10: =IF($A10="","",INDEX($DA$22:$DA$51,MATCH(SMALL($BV10:$CY10,30),$BV10:$CY10,0))) | BB10: =RAND() | BC10: =RAND() | BD10: =RAND() | BE10: =RAND() | BF10: =RAND() | BG10: =RAND() | BH10: =RAND() | BI10: =RAND() | ... CY10: =RAND() | DA10: TF09
A11: =IF(الطالبات!B8="","",الطالبات!B8) | B11: =IF(الطالبات!C8="","",الطالبات!C8) | C11: =IF($A11="","",INDEX($DA$2:$DA$21,MATCH(SMALL($BB11:$BU11,1),$BB11:$BU11,0))) | D11: =IF($A11="","",INDEX($DA$2:$DA$21,MATCH(SMALL($BB11:$BU11,2),$BB11:$BU11,0))) | E11: =IF($A11="","",INDEX($DA$2:$DA$21,MATCH(SMALL($BB11:$BU11,3),$BB11:$BU11,0))) | F11: =IF($A11="","",INDEX($DA$2:$DA$21,MATCH(SMALL($BB11:$BU11,4),$BB11:$BU11,0))) | G11: =IF($A11="","",INDEX($DA$2:$DA$21,MATCH(SMALL($BB11:$BU11,5),$BB11:$BU11,0))) | H11: =IF($A11="","",INDEX($DA$2:$DA$21,MATCH(SMALL($BB11:$BU11,6),$BB11:$BU11,0))) | I11: =IF($A11="","",INDEX($DA$2:$DA$21,MATCH(SMALL($BB11:$BU11,7),$BB11:$BU11,0))) | J11: =IF($A11="","",INDEX($DA$2:$DA$21,MATCH(SMALL($BB11:$BU11,8),$BB11:$BU11,0))) | K11: =IF($A11="","",INDEX($DA$2:$DA$21,MATCH(SMALL($BB11:$BU11,9),$BB11:$BU11,0))) | L11: =IF($A11="","",INDEX($DA$2:$DA$21,MATCH(SMALL($BB11:$BU11,10),$BB11:$BU11,0))) | M11: =IF($A11="","",INDEX($DA$2:$DA$21,MATCH(SMALL($BB11:$BU11,11),$BB11:$BU11,0))) | N11: =IF($A11="","",INDEX($DA$2:$DA$21,MATCH(SMALL($BB11:$BU11,12),$BB11:$BU11,0))) | O11: =IF($A11="","",INDEX($DA$2:$DA$21,MATCH(SMALL($BB11:$BU11,13),$BB11:$BU11,0))) | P11: =IF($A11="","",INDEX($DA$2:$DA$21,MATCH(SMALL($BB11:$BU11,14),$BB11:$BU11,0))) | Q11: =IF($A11="","",INDEX($DA$2:$DA$21,MATCH(SMALL($BB11:$BU11,15),$BB11:$BU11,0))) | R11: =IF($A11="","",INDEX($DA$2:$DA$21,MATCH(SMALL($BB11:$BU11,16),$BB11:$BU11,0))) | S11: =IF($A11="","",INDEX($DA$2:$DA$21,MATCH(SMALL($BB11:$BU11,17),$BB11:$BU11,0))) | T11: =IF($A11="","",INDEX($DA$2:$DA$21,MATCH(SMALL($BB11:$BU11,18),$BB11:$BU11,0))) | U11: =IF($A11="","",INDEX($DA$2:$DA$21,MATCH(SMALL($BB11:$BU11,19),$BB11:$BU11,0))) | V11: =IF($A11="","",INDEX($DA$2:$DA$21,MATCH(SMALL($BB11:$BU11,20),$BB11:$BU11,0))) | W11: =IF($A11="","",INDEX($DA$22:$DA$51,MATCH(SMALL($BV11:$CY11,1),$BV11:$CY11,0))) | X11: =IF($A11="","",INDEX($DA$22:$DA$51,MATCH(SMALL($BV11:$CY11,2),$BV11:$CY11,0))) | Y11: =IF($A11="","",INDEX($DA$22:$DA$51,MATCH(SMALL($BV11:$CY11,3),$BV11:$CY11,0))) | Z11: =IF($A11="","",INDEX($DA$22:$DA$51,MATCH(SMALL($BV11:$CY11,4),$BV11:$CY11,0))) | AA11: =IF($A11="","",INDEX($DA$22:$DA$51,MATCH(SMALL($BV11:$CY11,5),$BV11:$CY11,0))) | AB11: =IF($A11="","",INDEX($DA$22:$DA$51,MATCH(SMALL($BV11:$CY11,6),$BV11:$CY11,0))) | AC11: =IF($A11="","",INDEX($DA$22:$DA$51,MATCH(SMALL($BV11:$CY11,7),$BV11:$CY11,0))) | AD11: =IF($A11="","",INDEX($DA$22:$DA$51,MATCH(SMALL($BV11:$CY11,8),$BV11:$CY11,0))) | AE11: =IF($A11="","",INDEX($DA$22:$DA$51,MATCH(SMALL($BV11:$CY11,9),$BV11:$CY11,0))) | AF11: =IF($A11="","",INDEX($DA$22:$DA$51,MATCH(SMALL($BV11:$CY11,10),$BV11:$CY11,0))) | AG11: =IF($A11="","",INDEX($DA$22:$DA$51,MATCH(SMALL($BV11:$CY11,11),$BV11:$CY11,0))) | AH11: =IF($A11="","",INDEX($DA$22:$DA$51,MATCH(SMALL($BV11:$CY11,12),$BV11:$CY11,0))) | AI11: =IF($A11="","",INDEX($DA$22:$DA$51,MATCH(SMALL($BV11:$CY11,13),$BV11:$CY11,0))) | AJ11: =IF($A11="","",INDEX($DA$22:$DA$51,MATCH(SMALL($BV11:$CY11,14),$BV11:$CY11,0))) | AK11: =IF($A11="","",INDEX($DA$22:$DA$51,MATCH(SMALL($BV11:$CY11,15),$BV11:$CY11,0))) | AL11: =IF($A11="","",INDEX($DA$22:$DA$51,MATCH(SMALL($BV11:$CY11,16),$BV11:$CY11,0))) | AM11: =IF($A11="","",INDEX($DA$22:$DA$51,MATCH(SMALL($BV11:$CY11,17),$BV11:$CY11,0))) | AN11: =IF($A11="","",INDEX($DA$22:$DA$51,MATCH(SMALL($BV11:$CY11,18),$BV11:$CY11,0))) | AO11: =IF($A11="","",INDEX($DA$22:$DA$51,MATCH(SMALL($BV11:$CY11,19),$BV11:$CY11,0))) | AP11: =IF($A11="","",INDEX($DA$22:$DA$51,MATCH(SMALL($BV11:$CY11,20),$BV11:$CY11,0))) | AQ11: =IF($A11="","",INDEX($DA$22:$DA$51,MATCH(SMALL($BV11:$CY11,21),$BV11:$CY11,0))) | AR11: =IF($A11="","",INDEX($DA$22:$DA$51,MATCH(SMALL($BV11:$CY11,22),$BV11:$CY11,0))) | AS11: =IF($A11="","",INDEX($DA$22:$DA$51,MATCH(SMALL($BV11:$CY11,23),$BV11:$CY11,0))) | AT11: =IF($A11="","",INDEX($DA$22:$DA$51,MATCH(SMALL($BV11:$CY11,24),$BV11:$CY11,0))) | AU11: =IF($A11="","",INDEX($DA$22:$DA$51,MATCH(SMALL($BV11:$CY11,25),$BV11:$CY11,0))) | AV11: =IF($A11="","",INDEX($DA$22:$DA$51,MATCH(SMALL($BV11:$CY11,26),$BV11:$CY11,0))) | AW11: =IF($A11="","",INDEX($DA$22:$DA$51,MATCH(SMALL($BV11:$CY11,27),$BV11:$CY11,0))) | AX11: =IF($A11="","",INDEX($DA$22:$DA$51,MATCH(SMALL($BV11:$CY11,28),$BV11:$CY11,0))) | AY11: =IF($A11="","",INDEX($DA$22:$DA$51,MATCH(SMALL($BV11:$CY11,29),$BV11:$CY11,0))) | AZ11: =IF($A11="","",INDEX($DA$22:$DA$51,MATCH(SMALL($BV11:$CY11,30),$BV11:$CY11,0))) | BB11: =RAND() | BC11: =RAND() | BD11: =RAND() | BE11: =RAND() | BF11: =RAND() | BG11: =RAND() | BH11: =RAND() | BI11: =RAND() | ... CY11: =RAND() | DA11: TF10
A12: =IF(الطالبات!B9="","",الطالبات!B9) | B12: =IF(الطالبات!C9="","",الطالبات!C9) | C12: =IF($A12="","",INDEX($DA$2:$DA$21,MATCH(SMALL($BB12:$BU12,1),$BB12:$BU12,0))) | D12: =IF($A12="","",INDEX($DA$2:$DA$21,MATCH(SMALL($BB12:$BU12,2),$BB12:$BU12,0))) | E12: =IF($A12="","",INDEX($DA$2:$DA$21,MATCH(SMALL($BB12:$BU12,3),$BB12:$BU12,0))) | F12: =IF($A12="","",INDEX($DA$2:$DA$21,MATCH(SMALL($BB12:$BU12,4),$BB12:$BU12,0))) | G12: =IF($A12="","",INDEX($DA$2:$DA$21,MATCH(SMALL($BB12:$BU12,5),$BB12:$BU12,0))) | H12: =IF($A12="","",INDEX($DA$2:$DA$21,MATCH(SMALL($BB12:$BU12,6),$BB12:$BU12,0))) | I12: =IF($A12="","",INDEX($DA$2:$DA$21,MATCH(SMALL($BB12:$BU12,7),$BB12:$BU12,0))) | J12: =IF($A12="","",INDEX($DA$2:$DA$21,MATCH(SMALL($BB12:$BU12,8),$BB12:$BU12,0))) | K12: =IF($A12="","",INDEX($DA$2:$DA$21,MATCH(SMALL($BB12:$BU12,9),$BB12:$BU12,0))) | L12: =IF($A12="","",INDEX($DA$2:$DA$21,MATCH(SMALL($BB12:$BU12,10),$BB12:$BU12,0))) | M12: =IF($A12="","",INDEX($DA$2:$DA$21,MATCH(SMALL($BB12:$BU12,11),$BB12:$BU12,0))) | N12: =IF($A12="","",INDEX($DA$2:$DA$21,MATCH(SMALL($BB12:$BU12,12),$BB12:$BU12,0))) | O12: =IF($A12="","",INDEX($DA$2:$DA$21,MATCH(SMALL($BB12:$BU12,13),$BB12:$BU12,0))) | P12: =IF($A12="","",INDEX($DA$2:$DA$21,MATCH(SMALL($BB12:$BU12,14),$BB12:$BU12,0))) | Q12: =IF($A12="","",INDEX($DA$2:$DA$21,MATCH(SMALL($BB12:$BU12,15),$BB12:$BU12,0))) | R12: =IF($A12="","",INDEX($DA$2:$DA$21,MATCH(SMALL($BB12:$BU12,16),$BB12:$BU12,0))) | S12: =IF($A12="","",INDEX($DA$2:$DA$21,MATCH(SMALL($BB12:$BU12,17),$BB12:$BU12,0))) | T12: =IF($A12="","",INDEX($DA$2:$DA$21,MATCH(SMALL($BB12:$BU12,18),$BB12:$BU12,0))) | U12: =IF($A12="","",INDEX($DA$2:$DA$21,MATCH(SMALL($BB12:$BU12,19),$BB12:$BU12,0))) | V12: =IF($A12="","",INDEX($DA$2:$DA$21,MATCH(SMALL($BB12:$BU12,20),$BB12:$BU12,0))) | W12: =IF($A12="","",INDEX($DA$22:$DA$51,MATCH(SMALL($BV12:$CY12,1),$BV12:$CY12,0))) | X12: =IF($A12="","",INDEX($DA$22:$DA$51,MATCH(SMALL($BV12:$CY12,2),$BV12:$CY12,0))) | Y12: =IF($A12="","",INDEX($DA$22:$DA$51,MATCH(SMALL($BV12:$CY12,3),$BV12:$CY12,0))) | Z12: =IF($A12="","",INDEX($DA$22:$DA$51,MATCH(SMALL($BV12:$CY12,4),$BV12:$CY12,0))) | AA12: =IF($A12="","",INDEX($DA$22:$DA$51,MATCH(SMALL($BV12:$CY12,5),$BV12:$CY12,0))) | AB12: =IF($A12="","",INDEX($DA$22:$DA$51,MATCH(SMALL($BV12:$CY12,6),$BV12:$CY12,0))) | AC12: =IF($A12="","",INDEX($DA$22:$DA$51,MATCH(SMALL($BV12:$CY12,7),$BV12:$CY12,0))) | AD12: =IF($A12="","",INDEX($DA$22:$DA$51,MATCH(SMALL($BV12:$CY12,8),$BV12:$CY12,0))) | AE12: =IF($A12="","",INDEX($DA$22:$DA$51,MATCH(SMALL($BV12:$CY12,9),$BV12:$CY12,0))) | AF12: =IF($A12="","",INDEX($DA$22:$DA$51,MATCH(SMALL($BV12:$CY12,10),$BV12:$CY12,0))) | AG12: =IF($A12="","",INDEX($DA$22:$DA$51,MATCH(SMALL($BV12:$CY12,11),$BV12:$CY12,0))) | AH12: =IF($A12="","",INDEX($DA$22:$DA$51,MATCH(SMALL($BV12:$CY12,12),$BV12:$CY12,0))) | AI12: =IF($A12="","",INDEX($DA$22:$DA$51,MATCH(SMALL($BV12:$CY12,13),$BV12:$CY12,0))) | AJ12: =IF($A12="","",INDEX($DA$22:$DA$51,MATCH(SMALL($BV12:$CY12,14),$BV12:$CY12,0))) | AK12: =IF($A12="","",INDEX($DA$22:$DA$51,MATCH(SMALL($BV12:$CY12,15),$BV12:$CY12,0))) | AL12: =IF($A12="","",INDEX($DA$22:$DA$51,MATCH(SMALL($BV12:$CY12,16),$BV12:$CY12,0))) | AM12: =IF($A12="","",INDEX($DA$22:$DA$51,MATCH(SMALL($BV12:$CY12,17),$BV12:$CY12,0))) | AN12: =IF($A12="","",INDEX($DA$22:$DA$51,MATCH(SMALL($BV12:$CY12,18),$BV12:$CY12,0))) | AO12: =IF($A12="","",INDEX($DA$22:$DA$51,MATCH(SMALL($BV12:$CY12,19),$BV12:$CY12,0))) | AP12: =IF($A12="","",INDEX($DA$22:$DA$51,MATCH(SMALL($BV12:$CY12,20),$BV12:$CY12,0))) | AQ12: =IF($A12="","",INDEX($DA$22:$DA$51,MATCH(SMALL($BV12:$CY12,21),$BV12:$CY12,0))) | AR12: =IF($A12="","",INDEX($DA$22:$DA$51,MATCH(SMALL($BV12:$CY12,22),$BV12:$CY12,0))) | AS12: =IF($A12="","",INDEX($DA$22:$DA$51,MATCH(SMALL($BV12:$CY12,23),$BV12:$CY12,0))) | AT12: =IF($A12="","",INDEX($DA$22:$DA$51,MATCH(SMALL($BV12:$CY12,24),$BV12:$CY12,0))) | AU12: =IF($A12="","",INDEX($DA$22:$DA$51,MATCH(SMALL($BV12:$CY12,25),$BV12:$CY12,0))) | AV12: =IF($A12="","",INDEX($DA$22:$DA$51,MATCH(SMALL($BV12:$CY12,26),$BV12:$CY12,0))) | AW12: =IF($A12="","",INDEX($DA$22:$DA$51,MATCH(SMALL($BV12:$CY12,27),$BV12:$CY12,0))) | AX12: =IF($A12="","",INDEX($DA$22:$DA$51,MATCH(SMALL($BV12:$CY12,28),$BV12:$CY12,0))) | AY12: =IF($A12="","",INDEX($DA$22:$DA$51,MATCH(SMALL($BV12:$CY12,29),$BV12:$CY12,0))) | AZ12: =IF($A12="","",INDEX($DA$22:$DA$51,MATCH(SMALL($BV12:$CY12,30),$BV12:$CY12,0))) | BB12: =RAND() | BC12: =RAND() | BD12: =RAND() | BE12: =RAND() | BF12: =RAND() | BG12: =RAND() | BH12: =RAND() | BI12: =RAND() | ... CY12: =RAND() | DA12: TF11
A13: =IF(الطالبات!B10="","",الطالبات!B10) | B13: =IF(الطالبات!C10="","",الطالبات!C10) | C13: =IF($A13="","",INDEX($DA$2:$DA$21,MATCH(SMALL($BB13:$BU13,1),$BB13:$BU13,0))) | D13: =IF($A13="","",INDEX($DA$2:$DA$21,MATCH(SMALL($BB13:$BU13,2),$BB13:$BU13,0))) | E13: =IF($A13="","",INDEX($DA$2:$DA$21,MATCH(SMALL($BB13:$BU13,3),$BB13:$BU13,0))) | F13: =IF($A13="","",INDEX($DA$2:$DA$21,MATCH(SMALL($BB13:$BU13,4),$BB13:$BU13,0))) | G13: =IF($A13="","",INDEX($DA$2:$DA$21,MATCH(SMALL($BB13:$BU13,5),$BB13:$BU13,0))) | H13: =IF($A13="","",INDEX($DA$2:$DA$21,MATCH(SMALL($BB13:$BU13,6),$BB13:$BU13,0))) | I13: =IF($A13="","",INDEX($DA$2:$DA$21,MATCH(SMALL($BB13:$BU13,7),$BB13:$BU13,0))) | J13: =IF($A13="","",INDEX($DA$2:$DA$21,MATCH(SMALL($BB13:$BU13,8),$BB13:$BU13,0))) | K13: =IF($A13="","",INDEX($DA$2:$DA$21,MATCH(SMALL($BB13:$BU13,9),$BB13:$BU13,0))) | L13: =IF($A13="","",INDEX($DA$2:$DA$21,MATCH(SMALL($BB13:$BU13,10),$BB13:$BU13,0))) | M13: =IF($A13="","",INDEX($DA$2:$DA$21,MATCH(SMALL($BB13:$BU13,11),$BB13:$BU13,0))) | N13: =IF($A13="","",INDEX($DA$2:$DA$21,MATCH(SMALL($BB13:$BU13,12),$BB13:$BU13,0))) | O13: =IF($A13="","",INDEX($DA$2:$DA$21,MATCH(SMALL($BB13:$BU13,13),$BB13:$BU13,0))) | P13: =IF($A13="","",INDEX($DA$2:$DA$21,MATCH(SMALL($BB13:$BU13,14),$BB13:$BU13,0))) | Q13: =IF($A13="","",INDEX($DA$2:$DA$21,MATCH(SMALL($BB13:$BU13,15),$BB13:$BU13,0))) | R13: =IF($A13="","",INDEX($DA$2:$DA$21,MATCH(SMALL($BB13:$BU13,16),$BB13:$BU13,0))) | S13: =IF($A13="","",INDEX($DA$2:$DA$21,MATCH(SMALL($BB13:$BU13,17),$BB13:$BU13,0))) | T13: =IF($A13="","",INDEX($DA$2:$DA$21,MATCH(SMALL($BB13:$BU13,18),$BB13:$BU13,0))) | U13: =IF($A13="","",INDEX($DA$2:$DA$21,MATCH(SMALL($BB13:$BU13,19),$BB13:$BU13,0))) | V13: =IF($A13="","",INDEX($DA$2:$DA$21,MATCH(SMALL($BB13:$BU13,20),$BB13:$BU13,0))) | W13: =IF($A13="","",INDEX($DA$22:$DA$51,MATCH(SMALL($BV13:$CY13,1),$BV13:$CY13,0))) | X13: =IF($A13="","",INDEX($DA$22:$DA$51,MATCH(SMALL($BV13:$CY13,2),$BV13:$CY13,0))) | Y13: =IF($A13="","",INDEX($DA$22:$DA$51,MATCH(SMALL($BV13:$CY13,3),$BV13:$CY13,0))) | Z13: =IF($A13="","",INDEX($DA$22:$DA$51,MATCH(SMALL($BV13:$CY13,4),$BV13:$CY13,0))) | AA13: =IF($A13="","",INDEX($DA$22:$DA$51,MATCH(SMALL($BV13:$CY13,5),$BV13:$CY13,0))) | AB13: =IF($A13="","",INDEX($DA$22:$DA$51,MATCH(SMALL($BV13:$CY13,6),$BV13:$CY13,0))) | AC13: =IF($A13="","",INDEX($DA$22:$DA$51,MATCH(SMALL($BV13:$CY13,7),$BV13:$CY13,0))) | AD13: =IF($A13="","",INDEX($DA$22:$DA$51,MATCH(SMALL($BV13:$CY13,8),$BV13:$CY13,0))) | AE13: =IF($A13="","",INDEX($DA$22:$DA$51,MATCH(SMALL($BV13:$CY13,9),$BV13:$CY13,0))) | AF13: =IF($A13="","",INDEX($DA$22:$DA$51,MATCH(SMALL($BV13:$CY13,10),$BV13:$CY13,0))) | AG13: =IF($A13="","",INDEX($DA$22:$DA$51,MATCH(SMALL($BV13:$CY13,11),$BV13:$CY13,0))) | AH13: =IF($A13="","",INDEX($DA$22:$DA$51,MATCH(SMALL($BV13:$CY13,12),$BV13:$CY13,0))) | AI13: =IF($A13="","",INDEX($DA$22:$DA$51,MATCH(SMALL($BV13:$CY13,13),$BV13:$CY13,0))) | AJ13: =IF($A13="","",INDEX($DA$22:$DA$51,MATCH(SMALL($BV13:$CY13,14),$BV13:$CY13,0))) | AK13: =IF($A13="","",INDEX($DA$22:$DA$51,MATCH(SMALL($BV13:$CY13,15),$BV13:$CY13,0))) | AL13: =IF($A13="","",INDEX($DA$22:$DA$51,MATCH(SMALL($BV13:$CY13,16),$BV13:$CY13,0))) | AM13: =IF($A13="","",INDEX($DA$22:$DA$51,MATCH(SMALL($BV13:$CY13,17),$BV13:$CY13,0))) | AN13: =IF($A13="","",INDEX($DA$22:$DA$51,MATCH(SMALL($BV13:$CY13,18),$BV13:$CY13,0))) | AO13: =IF($A13="","",INDEX($DA$22:$DA$51,MATCH(SMALL($BV13:$CY13,19),$BV13:$CY13,0))) | AP13: =IF($A13="","",INDEX($DA$22:$DA$51,MATCH(SMALL($BV13:$CY13,20),$BV13:$CY13,0))) | AQ13: =IF($A13="","",INDEX($DA$22:$DA$51,MATCH(SMALL($BV13:$CY13,21),$BV13:$CY13,0))) | AR13: =IF($A13="","",INDEX($DA$22:$DA$51,MATCH(SMALL($BV13:$CY13,22),$BV13:$CY13,0))) | AS13: =IF($A13="","",INDEX($DA$22:$DA$51,MATCH(SMALL($BV13:$CY13,23),$BV13:$CY13,0))) | AT13: =IF($A13="","",INDEX($DA$22:$DA$51,MATCH(SMALL($BV13:$CY13,24),$BV13:$CY13,0))) | AU13: =IF($A13="","",INDEX($DA$22:$DA$51,MATCH(SMALL($BV13:$CY13,25),$BV13:$CY13,0))) | AV13: =IF($A13="","",INDEX($DA$22:$DA$51,MATCH(SMALL($BV13:$CY13,26),$BV13:$CY13,0))) | AW13: =IF($A13="","",INDEX($DA$22:$DA$51,MATCH(SMALL($BV13:$CY13,27),$BV13:$CY13,0))) | AX13: =IF($A13="","",INDEX($DA$22:$DA$51,MATCH(SMALL($BV13:$CY13,28),$BV13:$CY13,0))) | AY13: =IF($A13="","",INDEX($DA$22:$DA$51,MATCH(SMALL($BV13:$CY13,29),$BV13:$CY13,0))) | AZ13: =IF($A13="","",INDEX($DA$22:$DA$51,MATCH(SMALL($BV13:$CY13,30),$BV13:$CY13,0))) | BB13: =RAND() | BC13: =RAND() | BD13: =RAND() | BE13: =RAND() | BF13: =RAND() | BG13: =RAND() | BH13: =RAND() | BI13: =RAND() | ... CY13: =RAND() | DA13: TF12
A14: =IF(الطالبات!B11="","",الطالبات!B11) | B14: =IF(الطالبات!C11="","",الطالبات!C11) | C14: =IF($A14="","",INDEX($DA$2:$DA$21,MATCH(SMALL($BB14:$BU14,1),$BB14:$BU14,0))) | D14: =IF($A14="","",INDEX($DA$2:$DA$21,MATCH(SMALL($BB14:$BU14,2),$BB14:$BU14,0))) | E14: =IF($A14="","",INDEX($DA$2:$DA$21,MATCH(SMALL($BB14:$BU14,3),$BB14:$BU14,0))) | F14: =IF($A14="","",INDEX($DA$2:$DA$21,MATCH(SMALL($BB14:$BU14,4),$BB14:$BU14,0))) | G14: =IF($A14="","",INDEX($DA$2:$DA$21,MATCH(SMALL($BB14:$BU14,5),$BB14:$BU14,0))) | H14: =IF($A14="","",INDEX($DA$2:$DA$21,MATCH(SMALL($BB14:$BU14,6),$BB14:$BU14,0))) | I14: =IF($A14="","",INDEX($DA$2:$DA$21,MATCH(SMALL($BB14:$BU14,7),$BB14:$BU14,0))) | J14: =IF($A14="","",INDEX($DA$2:$DA$21,MATCH(SMALL($BB14:$BU14,8),$BB14:$BU14,0))) | K14: =IF($A14="","",INDEX($DA$2:$DA$21,MATCH(SMALL($BB14:$BU14,9),$BB14:$BU14,0))) | L14: =IF($A14="","",INDEX($DA$2:$DA$21,MATCH(SMALL($BB14:$BU14,10),$BB14:$BU14,0))) | M14: =IF($A14="","",INDEX($DA$2:$DA$21,MATCH(SMALL($BB14:$BU14,11),$BB14:$BU14,0))) | N14: =IF($A14="","",INDEX($DA$2:$DA$21,MATCH(SMALL($BB14:$BU14,12),$BB14:$BU14,0))) | O14: =IF($A14="","",INDEX($DA$2:$DA$21,MATCH(SMALL($BB14:$BU14,13),$BB14:$BU14,0))) | P14: =IF($A14="","",INDEX($DA$2:$DA$21,MATCH(SMALL($BB14:$BU14,14),$BB14:$BU14,0))) | Q14: =IF($A14="","",INDEX($DA$2:$DA$21,MATCH(SMALL($BB14:$BU14,15),$BB14:$BU14,0))) | R14: =IF($A14="","",INDEX($DA$2:$DA$21,MATCH(SMALL($BB14:$BU14,16),$BB14:$BU14,0))) | S14: =IF($A14="","",INDEX($DA$2:$DA$21,MATCH(SMALL($BB14:$BU14,17),$BB14:$BU14,0))) | T14: =IF($A14="","",INDEX($DA$2:$DA$21,MATCH(SMALL($BB14:$BU14,18),$BB14:$BU14,0))) | U14: =IF($A14="","",INDEX($DA$2:$DA$21,MATCH(SMALL($BB14:$BU14,19),$BB14:$BU14,0))) | V14: =IF($A14="","",INDEX($DA$2:$DA$21,MATCH(SMALL($BB14:$BU14,20),$BB14:$BU14,0))) | W14: =IF($A14="","",INDEX($DA$22:$DA$51,MATCH(SMALL($BV14:$CY14,1),$BV14:$CY14,0))) | X14: =IF($A14="","",INDEX($DA$22:$DA$51,MATCH(SMALL($BV14:$CY14,2),$BV14:$CY14,0))) | Y14: =IF($A14="","",INDEX($DA$22:$DA$51,MATCH(SMALL($BV14:$CY14,3),$BV14:$CY14,0))) | Z14: =IF($A14="","",INDEX($DA$22:$DA$51,MATCH(SMALL($BV14:$CY14,4),$BV14:$CY14,0))) | AA14: =IF($A14="","",INDEX($DA$22:$DA$51,MATCH(SMALL($BV14:$CY14,5),$BV14:$CY14,0))) | AB14: =IF($A14="","",INDEX($DA$22:$DA$51,MATCH(SMALL($BV14:$CY14,6),$BV14:$CY14,0))) | AC14: =IF($A14="","",INDEX($DA$22:$DA$51,MATCH(SMALL($BV14:$CY14,7),$BV14:$CY14,0))) | AD14: =IF($A14="","",INDEX($DA$22:$DA$51,MATCH(SMALL($BV14:$CY14,8),$BV14:$CY14,0))) | AE14: =IF($A14="","",INDEX($DA$22:$DA$51,MATCH(SMALL($BV14:$CY14,9),$BV14:$CY14,0))) | AF14: =IF($A14="","",INDEX($DA$22:$DA$51,MATCH(SMALL($BV14:$CY14,10),$BV14:$CY14,0))) | AG14: =IF($A14="","",INDEX($DA$22:$DA$51,MATCH(SMALL($BV14:$CY14,11),$BV14:$CY14,0))) | AH14: =IF($A14="","",INDEX($DA$22:$DA$51,MATCH(SMALL($BV14:$CY14,12),$BV14:$CY14,0))) | AI14: =IF($A14="","",INDEX($DA$22:$DA$51,MATCH(SMALL($BV14:$CY14,13),$BV14:$CY14,0))) | AJ14: =IF($A14="","",INDEX($DA$22:$DA$51,MATCH(SMALL($BV14:$CY14,14),$BV14:$CY14,0))) | AK14: =IF($A14="","",INDEX($DA$22:$DA$51,MATCH(SMALL($BV14:$CY14,15),$BV14:$CY14,0))) | AL14: =IF($A14="","",INDEX($DA$22:$DA$51,MATCH(SMALL($BV14:$CY14,16),$BV14:$CY14,0))) | AM14: =IF($A14="","",INDEX($DA$22:$DA$51,MATCH(SMALL($BV14:$CY14,17),$BV14:$CY14,0))) | AN14: =IF($A14="","",INDEX($DA$22:$DA$51,MATCH(SMALL($BV14:$CY14,18),$BV14:$CY14,0))) | AO14: =IF($A14="","",INDEX($DA$22:$DA$51,MATCH(SMALL($BV14:$CY14,19),$BV14:$CY14,0))) | AP14: =IF($A14="","",INDEX($DA$22:$DA$51,MATCH(SMALL($BV14:$CY14,20),$BV14:$CY14,0))) | AQ14: =IF($A14="","",INDEX($DA$22:$DA$51,MATCH(SMALL($BV14:$CY14,21),$BV14:$CY14,0))) | AR14: =IF($A14="","",INDEX($DA$22:$DA$51,MATCH(SMALL($BV14:$CY14,22),$BV14:$CY14,0))) | AS14: =IF($A14="","",INDEX($DA$22:$DA$51,MATCH(SMALL($BV14:$CY14,23),$BV14:$CY14,0))) | AT14: =IF($A14="","",INDEX($DA$22:$DA$51,MATCH(SMALL($BV14:$CY14,24),$BV14:$CY14,0))) | AU14: =IF($A14="","",INDEX($DA$22:$DA$51,MATCH(SMALL($BV14:$CY14,25),$BV14:$CY14,0))) | AV14: =IF($A14="","",INDEX($DA$22:$DA$51,MATCH(SMALL($BV14:$CY14,26),$BV14:$CY14,0))) | AW14: =IF($A14="","",INDEX($DA$22:$DA$51,MATCH(SMALL($BV14:$CY14,27),$BV14:$CY14,0))) | AX14: =IF($A14="","",INDEX($DA$22:$DA$51,MATCH(SMALL($BV14:$CY14,28),$BV14:$CY14,0))) | AY14: =IF($A14="","",INDEX($DA$22:$DA$51,MATCH(SMALL($BV14:$CY14,29),$BV14:$CY14,0))) | AZ14: =IF($A14="","",INDEX($DA$22:$DA$51,MATCH(SMALL($BV14:$CY14,30),$BV14:$CY14,0))) | BB14: =RAND() | BC14: =RAND() | BD14: =RAND() | BE14: =RAND() | BF14: =RAND() | BG14: =RAND() | BH14: =RAND() | BI14: =RAND() | ... CY14: =RAND() | DA14: TF13
A15: =IF(الطالبات!B12="","",الطالبات!B12) | B15: =IF(الطالبات!C12="","",الطالبات!C12) | C15: =IF($A15="","",INDEX($DA$2:$DA$21,MATCH(SMALL($BB15:$BU15,1),$BB15:$BU15,0))) | D15: =IF($A15="","",INDEX($DA$2:$DA$21,MATCH(SMALL($BB15:$BU15,2),$BB15:$BU15,0))) | E15: =IF($A15="","",INDEX($DA$2:$DA$21,MATCH(SMALL($BB15:$BU15,3),$BB15:$BU15,0))) | F15: =IF($A15="","",INDEX($DA$2:$DA$21,MATCH(SMALL($BB15:$BU15,4),$BB15:$BU15,0))) | G15: =IF($A15="","",INDEX($DA$2:$DA$21,MATCH(SMALL($BB15:$BU15,5),$BB15:$BU15,0))) | H15: =IF($A15="","",INDEX($DA$2:$DA$21,MATCH(SMALL($BB15:$BU15,6),$BB15:$BU15,0))) | I15: =IF($A15="","",INDEX($DA$2:$DA$21,MATCH(SMALL($BB15:$BU15,7),$BB15:$BU15,0))) | J15: =IF($A15="","",INDEX($DA$2:$DA$21,MATCH(SMALL($BB15:$BU15,8),$BB15:$BU15,0))) | K15: =IF($A15="","",INDEX($DA$2:$DA$21,MATCH(SMALL($BB15:$BU15,9),$BB15:$BU15,0))) | L15: =IF($A15="","",INDEX($DA$2:$DA$21,MATCH(SMALL($BB15:$BU15,10),$BB15:$BU15,0))) | M15: =IF($A15="","",INDEX($DA$2:$DA$21,MATCH(SMALL($BB15:$BU15,11),$BB15:$BU15,0))) | N15: =IF($A15="","",INDEX($DA$2:$DA$21,MATCH(SMALL($BB15:$BU15,12),$BB15:$BU15,0))) | O15: =IF($A15="","",INDEX($DA$2:$DA$21,MATCH(SMALL($BB15:$BU15,13),$BB15:$BU15,0))) | P15: =IF($A15="","",INDEX($DA$2:$DA$21,MATCH(SMALL($BB15:$BU15,14),$BB15:$BU15,0))) | Q15: =IF($A15="","",INDEX($DA$2:$DA$21,MATCH(SMALL($BB15:$BU15,15),$BB15:$BU15,0))) | R15: =IF($A15="","",INDEX($DA$2:$DA$21,MATCH(SMALL($BB15:$BU15,16),$BB15:$BU15,0))) | S15: =IF($A15="","",INDEX($DA$2:$DA$21,MATCH(SMALL($BB15:$BU15,17),$BB15:$BU15,0))) | T15: =IF($A15="","",INDEX($DA$2:$DA$21,MATCH(SMALL($BB15:$BU15,18),$BB15:$BU15,0))) | U15: =IF($A15="","",INDEX($DA$2:$DA$21,MATCH(SMALL($BB15:$BU15,19),$BB15:$BU15,0))) | V15: =IF($A15="","",INDEX($DA$2:$DA$21,MATCH(SMALL($BB15:$BU15,20),$BB15:$BU15,0))) | W15: =IF($A15="","",INDEX($DA$22:$DA$51,MATCH(SMALL($BV15:$CY15,1),$BV15:$CY15,0))) | X15: =IF($A15="","",INDEX($DA$22:$DA$51,MATCH(SMALL($BV15:$CY15,2),$BV15:$CY15,0))) | Y15: =IF($A15="","",INDEX($DA$22:$DA$51,MATCH(SMALL($BV15:$CY15,3),$BV15:$CY15,0))) | Z15: =IF($A15="","",INDEX($DA$22:$DA$51,MATCH(SMALL($BV15:$CY15,4),$BV15:$CY15,0))) | AA15: =IF($A15="","",INDEX($DA$22:$DA$51,MATCH(SMALL($BV15:$CY15,5),$BV15:$CY15,0))) | AB15: =IF($A15="","",INDEX($DA$22:$DA$51,MATCH(SMALL($BV15:$CY15,6),$BV15:$CY15,0))) | AC15: =IF($A15="","",INDEX($DA$22:$DA$51,MATCH(SMALL($BV15:$CY15,7),$BV15:$CY15,0))) | AD15: =IF($A15="","",INDEX($DA$22:$DA$51,MATCH(SMALL($BV15:$CY15,8),$BV15:$CY15,0))) | AE15: =IF($A15="","",INDEX($DA$22:$DA$51,MATCH(SMALL($BV15:$CY15,9),$BV15:$CY15,0))) | AF15: =IF($A15="","",INDEX($DA$22:$DA$51,MATCH(SMALL($BV15:$CY15,10),$BV15:$CY15,0))) | AG15: =IF($A15="","",INDEX($DA$22:$DA$51,MATCH(SMALL($BV15:$CY15,11),$BV15:$CY15,0))) | AH15: =IF($A15="","",INDEX($DA$22:$DA$51,MATCH(SMALL($BV15:$CY15,12),$BV15:$CY15,0))) | AI15: =IF($A15="","",INDEX($DA$22:$DA$51,MATCH(SMALL($BV15:$CY15,13),$BV15:$CY15,0))) | AJ15: =IF($A15="","",INDEX($DA$22:$DA$51,MATCH(SMALL($BV15:$CY15,14),$BV15:$CY15,0))) | AK15: =IF($A15="","",INDEX($DA$22:$DA$51,MATCH(SMALL($BV15:$CY15,15),$BV15:$CY15,0))) | AL15: =IF($A15="","",INDEX($DA$22:$DA$51,MATCH(SMALL($BV15:$CY15,16),$BV15:$CY15,0))) | AM15: =IF($A15="","",INDEX($DA$22:$DA$51,MATCH(SMALL($BV15:$CY15,17),$BV15:$CY15,0))) | AN15: =IF($A15="","",INDEX($DA$22:$DA$51,MATCH(SMALL($BV15:$CY15,18),$BV15:$CY15,0))) | AO15: =IF($A15="","",INDEX($DA$22:$DA$51,MATCH(SMALL($BV15:$CY15,19),$BV15:$CY15,0))) | AP15: =IF($A15="","",INDEX($DA$22:$DA$51,MATCH(SMALL($BV15:$CY15,20),$BV15:$CY15,0))) | AQ15: =IF($A15="","",INDEX($DA$22:$DA$51,MATCH(SMALL($BV15:$CY15,21),$BV15:$CY15,0))) | AR15: =IF($A15="","",INDEX($DA$22:$DA$51,MATCH(SMALL($BV15:$CY15,22),$BV15:$CY15,0))) | AS15: =IF($A15="","",INDEX($DA$22:$DA$51,MATCH(SMALL($BV15:$CY15,23),$BV15:$CY15,0))) | AT15: =IF($A15="","",INDEX($DA$22:$DA$51,MATCH(SMALL($BV15:$CY15,24),$BV15:$CY15,0))) | AU15: =IF($A15="","",INDEX($DA$22:$DA$51,MATCH(SMALL($BV15:$CY15,25),$BV15:$CY15,0))) | AV15: =IF($A15="","",INDEX($DA$22:$DA$51,MATCH(SMALL($BV15:$CY15,26),$BV15:$CY15,0))) | AW15: =IF($A15="","",INDEX($DA$22:$DA$51,MATCH(SMALL($BV15:$CY15,27),$BV15:$CY15,0))) | AX15: =IF($A15="","",INDEX($DA$22:$DA$51,MATCH(SMALL($BV15:$CY15,28),$BV15:$CY15,0))) | AY15: =IF($A15="","",INDEX($DA$22:$DA$51,MATCH(SMALL($BV15:$CY15,29),$BV15:$CY15,0))) | AZ15: =IF($A15="","",INDEX($DA$22:$DA$51,MATCH(SMALL($BV15:$CY15,30),$BV15:$CY15,0))) | BB15: =RAND() | BC15: =RAND() | BD15: =RAND() | BE15: =RAND() | BF15: =RAND() | BG15: =RAND() | BH15: =RAND() | BI15: =RAND() | ... CY15: =RAND() | DA15: TF14
A16: =IF(الطالبات!B13="","",الطالبات!B13) | B16: =IF(الطالبات!C13="","",الطالبات!C13) | C16: =IF($A16="","",INDEX($DA$2:$DA$21,MATCH(SMALL($BB16:$BU16,1),$BB16:$BU16,0))) | D16: =IF($A16="","",INDEX($DA$2:$DA$21,MATCH(SMALL($BB16:$BU16,2),$BB16:$BU16,0))) | E16: =IF($A16="","",INDEX($DA$2:$DA$21,MATCH(SMALL($BB16:$BU16,3),$BB16:$BU16,0))) | F16: =IF($A16="","",INDEX($DA$2:$DA$21,MATCH(SMALL($BB16:$BU16,4),$BB16:$BU16,0))) | G16: =IF($A16="","",INDEX($DA$2:$DA$21,MATCH(SMALL($BB16:$BU16,5),$BB16:$BU16,0))) | H16: =IF($A16="","",INDEX($DA$2:$DA$21,MATCH(SMALL($BB16:$BU16,6),$BB16:$BU16,0))) | I16: =IF($A16="","",INDEX($DA$2:$DA$21,MATCH(SMALL($BB16:$BU16,7),$BB16:$BU16,0))) | J16: =IF($A16="","",INDEX($DA$2:$DA$21,MATCH(SMALL($BB16:$BU16,8),$BB16:$BU16,0))) | K16: =IF($A16="","",INDEX($DA$2:$DA$21,MATCH(SMALL($BB16:$BU16,9),$BB16:$BU16,0))) | L16: =IF($A16="","",INDEX($DA$2:$DA$21,MATCH(SMALL($BB16:$BU16,10),$BB16:$BU16,0))) | M16: =IF($A16="","",INDEX($DA$2:$DA$21,MATCH(SMALL($BB16:$BU16,11),$BB16:$BU16,0))) | N16: =IF($A16="","",INDEX($DA$2:$DA$21,MATCH(SMALL($BB16:$BU16,12),$BB16:$BU16,0))) | O16: =IF($A16="","",INDEX($DA$2:$DA$21,MATCH(SMALL($BB16:$BU16,13),$BB16:$BU16,0))) | P16: =IF($A16="","",INDEX($DA$2:$DA$21,MATCH(SMALL($BB16:$BU16,14),$BB16:$BU16,0))) | Q16: =IF($A16="","",INDEX($DA$2:$DA$21,MATCH(SMALL($BB16:$BU16,15),$BB16:$BU16,0))) | R16: =IF($A16="","",INDEX($DA$2:$DA$21,MATCH(SMALL($BB16:$BU16,16),$BB16:$BU16,0))) | S16: =IF($A16="","",INDEX($DA$2:$DA$21,MATCH(SMALL($BB16:$BU16,17),$BB16:$BU16,0))) | T16: =IF($A16="","",INDEX($DA$2:$DA$21,MATCH(SMALL($BB16:$BU16,18),$BB16:$BU16,0))) | U16: =IF($A16="","",INDEX($DA$2:$DA$21,MATCH(SMALL($BB16:$BU16,19),$BB16:$BU16,0))) | V16: =IF($A16="","",INDEX($DA$2:$DA$21,MATCH(SMALL($BB16:$BU16,20),$BB16:$BU16,0))) | W16: =IF($A16="","",INDEX($DA$22:$DA$51,MATCH(SMALL($BV16:$CY16,1),$BV16:$CY16,0))) | X16: =IF($A16="","",INDEX($DA$22:$DA$51,MATCH(SMALL($BV16:$CY16,2),$BV16:$CY16,0))) | Y16: =IF($A16="","",INDEX($DA$22:$DA$51,MATCH(SMALL($BV16:$CY16,3),$BV16:$CY16,0))) | Z16: =IF($A16="","",INDEX($DA$22:$DA$51,MATCH(SMALL($BV16:$CY16,4),$BV16:$CY16,0))) | AA16: =IF($A16="","",INDEX($DA$22:$DA$51,MATCH(SMALL($BV16:$CY16,5),$BV16:$CY16,0))) | AB16: =IF($A16="","",INDEX($DA$22:$DA$51,MATCH(SMALL($BV16:$CY16,6),$BV16:$CY16,0))) | AC16: =IF($A16="","",INDEX($DA$22:$DA$51,MATCH(SMALL($BV16:$CY16,7),$BV16:$CY16,0))) | AD16: =IF($A16="","",INDEX($DA$22:$DA$51,MATCH(SMALL($BV16:$CY16,8),$BV16:$CY16,0))) | AE16: =IF($A16="","",INDEX($DA$22:$DA$51,MATCH(SMALL($BV16:$CY16,9),$BV16:$CY16,0))) | AF16: =IF($A16="","",INDEX($DA$22:$DA$51,MATCH(SMALL($BV16:$CY16,10),$BV16:$CY16,0))) | AG16: =IF($A16="","",INDEX($DA$22:$DA$51,MATCH(SMALL($BV16:$CY16,11),$BV16:$CY16,0))) | AH16: =IF($A16="","",INDEX($DA$22:$DA$51,MATCH(SMALL($BV16:$CY16,12),$BV16:$CY16,0))) | AI16: =IF($A16="","",INDEX($DA$22:$DA$51,MATCH(SMALL($BV16:$CY16,13),$BV16:$CY16,0))) | AJ16: =IF($A16="","",INDEX($DA$22:$DA$51,MATCH(SMALL($BV16:$CY16,14),$BV16:$CY16,0))) | AK16: =IF($A16="","",INDEX($DA$22:$DA$51,MATCH(SMALL($BV16:$CY16,15),$BV16:$CY16,0))) | AL16: =IF($A16="","",INDEX($DA$22:$DA$51,MATCH(SMALL($BV16:$CY16,16),$BV16:$CY16,0))) | AM16: =IF($A16="","",INDEX($DA$22:$DA$51,MATCH(SMALL($BV16:$CY16,17),$BV16:$CY16,0))) | AN16: =IF($A16="","",INDEX($DA$22:$DA$51,MATCH(SMALL($BV16:$CY16,18),$BV16:$CY16,0))) | AO16: =IF($A16="","",INDEX($DA$22:$DA$51,MATCH(SMALL($BV16:$CY16,19),$BV16:$CY16,0))) | AP16: =IF($A16="","",INDEX($DA$22:$DA$51,MATCH(SMALL($BV16:$CY16,20),$BV16:$CY16,0))) | AQ16: =IF($A16="","",INDEX($DA$22:$DA$51,MATCH(SMALL($BV16:$CY16,21),$BV16:$CY16,0))) | AR16: =IF($A16="","",INDEX($DA$22:$DA$51,MATCH(SMALL($BV16:$CY16,22),$BV16:$CY16,0))) | AS16: =IF($A16="","",INDEX($DA$22:$DA$51,MATCH(SMALL($BV16:$CY16,23),$BV16:$CY16,0))) | AT16: =IF($A16="","",INDEX($DA$22:$DA$51,MATCH(SMALL($BV16:$CY16,24),$BV16:$CY16,0))) | AU16: =IF($A16="","",INDEX($DA$22:$DA$51,MATCH(SMALL($BV16:$CY16,25),$BV16:$CY16,0))) | AV16: =IF($A16="","",INDEX($DA$22:$DA$51,MATCH(SMALL($BV16:$CY16,26),$BV16:$CY16,0))) | AW16: =IF($A16="","",INDEX($DA$22:$DA$51,MATCH(SMALL($BV16:$CY16,27),$BV16:$CY16,0))) | AX16: =IF($A16="","",INDEX($DA$22:$DA$51,MATCH(SMALL($BV16:$CY16,28),$BV16:$CY16,0))) | AY16: =IF($A16="","",INDEX($DA$22:$DA$51,MATCH(SMALL($BV16:$CY16,29),$BV16:$CY16,0))) | AZ16: =IF($A16="","",INDEX($DA$22:$DA$51,MATCH(SMALL($BV16:$CY16,30),$BV16:$CY16,0))) | BB16: =RAND() | BC16: =RAND() | BD16: =RAND() | BE16: =RAND() | BF16: =RAND() | BG16: =RAND() | BH16: =RAND() | BI16: =RAND() | ... CY16: =RAND() | DA16: TF15
